<mujoco model="two_pandas_nohand_with_tdcr">
  <!--
  ╔══════════════════════════════════════════════════════╗
  ║  TDCR SCALE FACTOR = 0.125                                    ║
  ║  Generated by generate_tdcr_xml.py                  ║
  ║  Panda arm geometry is NOT scaled.                  ║
  ╚══════════════════════════════════════════════════════╝
  -->
  <compiler angle="radian" meshdir="assets" autolimits="true"/>
  <option integrator="implicitfast" impratio="10" gravity="0 0 -9.81"/>
  <size nconmax="5000" njmax="5000"/>

  <statistic center="0 0 0.6" extent="1.8"/>

  <visual>
    <headlight diffuse="0.6 0.6 0.6" ambient="0.3 0.3 0.3" specular="0 0 0"/>
    <rgba haze="0.15 0.25 0.35 1"/>
    <global azimuth="120" elevation="-20"/>
  </visual>

  <!-- ═══════════════════════════════════════════════
       DEFAULTS
  ════════════════════════════════════════════════════ -->
  <default>
    <default class="panda">
      <material specular="0.5" shininess="0.25"/>
      <joint armature="0.1" damping="1" axis="0 0 1" range="-2.8973 2.8973"/>
      <general dyntype="none" biastype="affine" ctrlrange="-2.8973 2.8973" forcerange="-87 87"/>
      <default class="panda/visual">
        <geom type="mesh" contype="0" conaffinity="0" group="2"/>
      </default>
      <default class="panda/collision">
        <geom type="mesh" group="3"/>
      </default>
      <site size="0.001" rgba="0.5 0.5 0.5 0.3" group="4"/>
    </default>
  </default>

  <!-- ═══════════════════════════════════════════════
       ASSETS
  ════════════════════════════════════════════════════ -->
  <asset>
    <texture type="skybox" builtin="gradient" rgb1="0.3 0.5 0.7" rgb2="0 0 0" width="512" height="3072"/>
    <texture type="2d" name="groundplane" builtin="checker" mark="edge"
      rgb1="0.2 0.3 0.4" rgb2="0.1 0.2 0.3" markrgb="0.8 0.8 0.8" width="300" height="300"/>
    <material name="groundplane" texture="groundplane" texuniform="true" texrepeat="5 5" reflectance="0.2"/>
    <material name="base_mat" rgba="0.25 0.25 0.28 1" reflectance="0.3"/>
    <material name="pole_mat" rgba="0.55 0.55 0.60 1" reflectance="0.5"/>

    <!-- panda materials -->
    <material class="panda" name="white"      rgba="1 1 1 1"/>
    <material class="panda" name="off_white"  rgba="0.901961 0.921569 0.929412 1"/>
    <material class="panda" name="dark_grey"  rgba="0.25 0.25 0.25 1"/>
    <material class="panda" name="green"      rgba="0 1 0 1"/>
    <material class="panda" name="light_blue" rgba="0.039216 0.541176 0.780392 1"/>

    <!-- panda collision meshes — UNSCALED -->
    <mesh name="link0_c"  file="link0.stl"/>
    <mesh name="link1_c"  file="link1.stl"/>
    <mesh name="link2_c"  file="link2.stl"/>
    <mesh name="link3_c"  file="link3.stl"/>
    <mesh name="link4_c"  file="link4.stl"/>
    <mesh name="link5_c0" file="link5_collision_0.obj"/>
    <mesh name="link5_c1" file="link5_collision_1.obj"/>
    <mesh name="link5_c2" file="link5_collision_2.obj"/>
    <mesh name="link6_c"  file="link6.stl"/>
    <mesh name="link7_c"  file="link7.stl"/>

    <!-- panda visual meshes — UNSCALED -->
    <mesh file="link0_0.obj"/>  <mesh file="link0_1.obj"/>  <mesh file="link0_2.obj"/>
    <mesh file="link0_3.obj"/>  <mesh file="link0_4.obj"/>  <mesh file="link0_5.obj"/>
    <mesh file="link0_7.obj"/>  <mesh file="link0_8.obj"/>  <mesh file="link0_9.obj"/>
    <mesh file="link0_10.obj"/> <mesh file="link0_11.obj"/>
    <mesh file="link1.obj"/>    <mesh file="link2.obj"/>
    <mesh file="link3_0.obj"/>  <mesh file="link3_1.obj"/>  <mesh file="link3_2.obj"/>  <mesh file="link3_3.obj"/>
    <mesh file="link4_0.obj"/>  <mesh file="link4_1.obj"/>  <mesh file="link4_2.obj"/>  <mesh file="link4_3.obj"/>
    <mesh file="link5_0.obj"/>  <mesh file="link5_1.obj"/>  <mesh file="link5_2.obj"/>
    <mesh file="link6_0.obj"/>  <mesh file="link6_1.obj"/>  <mesh file="link6_2.obj"/>  <mesh file="link6_3.obj"/>
    <mesh file="link6_4.obj"/>  <mesh file="link6_5.obj"/>  <mesh file="link6_6.obj"/>  <mesh file="link6_7.obj"/>
    <mesh file="link6_8.obj"/>  <mesh file="link6_9.obj"/>  <mesh file="link6_10.obj"/> <mesh file="link6_11.obj"/>
    <mesh file="link6_12.obj"/> <mesh file="link6_13.obj"/> <mesh file="link6_14.obj"/> <mesh file="link6_15.obj"/>
    <mesh file="link6_16.obj"/>
    <mesh file="link7_0.obj"/>  <mesh file="link7_1.obj"/>  <mesh file="link7_2.obj"/>  <mesh file="link7_3.obj"/>
    <mesh file="link7_4.obj"/>  <mesh file="link7_5.obj"/>  <mesh file="link7_6.obj"/>  <mesh file="link7_7.obj"/>

    <!-- TDCR meshes — SCALED by 0.125 -->
    <mesh name="platform_mesh"   file="3D/p_platform.STL"   scale="0.000125000 0.000125000 0.000125000"/>
    <mesh name="base_mesh"       file="3D/P_0Base.STL"       scale="0.000125000 0.000125000 0.000125000"/>
    <mesh name="segment_mesh"    file="3D/P_1_3.STL"         scale="0.000125000 0.000125000 0.000125000"/>
    <mesh name="segment_2_mesh"  file="3D/P_1_3.STL"         scale="0.000114083 0.000114083 0.000114083"/>
    <mesh name="segment_3_mesh"  file="3D/P_1_3.STL"         scale="0.000104119 0.000104119 0.000104119"/>
    <mesh name="segment_4_mesh"  file="3D/P_1_3.STL"         scale="0.000095024 0.000095024 0.000095024"/>
    <mesh name="segment_5_mesh"  file="3D/P_1_3.STL"         scale="0.000086725 0.000086725 0.000086725"/>
    <mesh name="segment_6_mesh"  file="3D/P_1_3.STL"         scale="0.000079150 0.000079150 0.000079150"/>
    <mesh name="segment_7_mesh"  file="3D/P_1_3.STL"         scale="0.000072238 0.000072238 0.000072238"/>
    <mesh name="segment_8_mesh"  file="3D/P_1_3.STL"         scale="0.000065928 0.000065928 0.000065928"/>
    <mesh name="segment_9_mesh"  file="3D/P_1_3.STL"         scale="0.000060169 0.000060169 0.000060169"/>
    <mesh name="segment_10_mesh" file="3D/P_1_3.STL"         scale="0.000054914 0.000054914 0.000054914"/>
    <mesh name="segment_11_mesh" file="3D/P_1_3.STL"         scale="0.000050118 0.000050118 0.000050118"/>
    <mesh name="segment_12_mesh" file="3D/P_1_3.STL"         scale="0.000045740 0.000045740 0.000045740"/>
    <mesh name="gripper_base"    file="3D_Gripper/gripper_base.STL" scale="0.125 0.125 0.125"/>
    <mesh name="gripper"         file="3D_Gripper/gripper.STL"      scale="0.125 0.125 0.125"/>
  </asset>

  <!-- ═══════════════════════════════════════════════
       WORLD
  ════════════════════════════════════════════════════ -->
  <worldbody>
    <light pos="0 0 2.5" dir="0 0 -1" directional="true"/>
    <light pos="-1 0 2" dir="0.5 0 -1"  directional="false" diffuse="0.4 0.4 0.4"/>
    <light pos=" 1 0 2" dir="-0.5 0 -1" directional="false" diffuse="0.4 0.4 0.4"/>
    <geom name="floor" size="0 0 0.05" type="plane" material="groundplane"/>

    <!-- ── Cuboid base platform ── -->
    <geom name="base_platform" type="box"
          size="0.85 0.3 0.1" pos="0 0 0.1" material="base_mat"/>
    <geom name="centre_pole" type="cylinder"
          fromto="0 0 0.2  0 0 0.9" size="0.04" material="pole_mat"/>
    <geom name="pole_cap" type="sphere"
          size="0.055" pos="0 0 0.92" material="pole_mat"/>

    <!-- ══════════════════════════════════════════════════════
         PANDA 1  –  left (x=-0.55), facing +Y  — PANDA UNSCALED
    ═══════════════════════════════════════════════════════════ -->
    <body name="p1_link0" childclass="panda" pos="-0.55 0 0.2" euler="0 0 1.5708">
      <inertial mass="0.629769" pos="-0.041018 -0.00014 0.049974"
        fullinertia="0.00315 0.00388 0.004285 8.2904e-7 0.00015 8.2299e-6"/>
      <geom mesh="link0_0"  material="off_white"  class="panda/visual"/>
      <geom mesh="link0_1"  material="dark_grey"  class="panda/visual"/>
      <geom mesh="link0_2"  material="off_white"  class="panda/visual"/>
      <geom mesh="link0_3"  material="dark_grey"  class="panda/visual"/>
      <geom mesh="link0_4"  material="off_white"  class="panda/visual"/>
      <geom mesh="link0_5"  material="dark_grey"  class="panda/visual"/>
      <geom mesh="link0_7"  material="white"      class="panda/visual"/>
      <geom mesh="link0_8"  material="white"      class="panda/visual"/>
      <geom mesh="link0_9"  material="dark_grey"  class="panda/visual"/>
      <geom mesh="link0_10" material="off_white"  class="panda/visual"/>
      <geom mesh="link0_11" material="white"      class="panda/visual"/>
      <geom mesh="link0_c"  class="panda/collision"/>
      <body name="p1_link1" pos="0 0 0.333">
        <inertial mass="4.970684" pos="0.003875 0.002081 -0.04762"
          fullinertia="0.70337 0.70661 0.0091170 -0.00013900 0.0067720 0.019169"/>
        <joint name="p1_joint1"/>
        <geom material="white" mesh="link1" class="panda/visual"/>
        <geom mesh="link1_c" class="panda/collision"/>
        <body name="p1_link2" quat="1 -1 0 0">
          <inertial mass="0.646926" pos="-0.003141 -0.02872 0.003495"
            fullinertia="0.0079620 2.8110e-2 2.5995e-2 -3.925e-3 1.0254e-2 7.04e-4"/>
          <joint name="p1_joint2" range="-1.7628 1.7628"/>
          <geom material="white" mesh="link2" class="panda/visual"/>
          <geom mesh="link2_c" class="panda/collision"/>
          <body name="p1_link3" pos="0 -0.316 0" quat="1 1 0 0">
            <joint name="p1_joint3"/>
            <inertial mass="3.228604" pos="2.7518e-2 3.9252e-2 -6.6502e-2"
              fullinertia="3.7242e-2 3.6155e-2 1.083e-2 -4.761e-3 -1.1396e-2 -1.2805e-2"/>
            <geom mesh="link3_0" material="white"     class="panda/visual"/>
            <geom mesh="link3_1" material="white"     class="panda/visual"/>
            <geom mesh="link3_2" material="white"     class="panda/visual"/>
            <geom mesh="link3_3" material="dark_grey" class="panda/visual"/>
            <geom mesh="link3_c" class="panda/collision"/>
            <body name="p1_link4" pos="0.0825 0 0" quat="1 1 0 0">
              <inertial mass="3.587895" pos="-5.317e-2 1.04419e-1 2.7454e-2"
                fullinertia="2.5853e-2 1.9552e-2 2.8323e-2 7.796e-3 -1.332e-3 8.641e-3"/>
              <joint name="p1_joint4" range="-3.0718 -0.0698"/>
              <geom mesh="link4_0" material="white"     class="panda/visual"/>
              <geom mesh="link4_1" material="white"     class="panda/visual"/>
              <geom mesh="link4_2" material="dark_grey" class="panda/visual"/>
              <geom mesh="link4_3" material="white"     class="panda/visual"/>
              <geom mesh="link4_c" class="panda/collision"/>
              <body name="p1_link5" pos="-0.0825 0.384 0" quat="1 -1 0 0">
                <inertial mass="1.225946" pos="-1.1953e-2 4.1065e-2 -3.8437e-2"
                  fullinertia="3.5549e-2 2.9474e-2 8.627e-3 -2.117e-3 -4.037e-3 2.29e-4"/>
                <joint name="p1_joint5"/>
                <geom mesh="link5_0" material="dark_grey" class="panda/visual"/>
                <geom mesh="link5_1" material="white"     class="panda/visual"/>
                <geom mesh="link5_2" material="white"     class="panda/visual"/>
                <geom mesh="link5_c0" class="panda/collision"/>
                <geom mesh="link5_c1" class="panda/collision"/>
                <geom mesh="link5_c2" class="panda/collision"/>
                <body name="p1_link6" quat="1 1 0 0">
                  <inertial mass="1.666555" pos="6.0149e-2 -1.4117e-2 -1.0517e-2"
                    fullinertia="1.964e-3 4.354e-3 5.433e-3 1.09e-4 -1.158e-3 3.41e-4"/>
                  <joint name="p1_joint6" range="-0.0175 3.7525"/>
                  <geom mesh="link6_0"  material="off_white"  class="panda/visual"/>
                  <geom mesh="link6_1"  material="white"      class="panda/visual"/>
                  <geom mesh="link6_2"  material="dark_grey"  class="panda/visual"/>
                  <geom mesh="link6_3"  material="white"      class="panda/visual"/>
                  <geom mesh="link6_4"  material="white"      class="panda/visual"/>
                  <geom mesh="link6_5"  material="white"      class="panda/visual"/>
                  <geom mesh="link6_6"  material="white"      class="panda/visual"/>
                  <geom mesh="link6_7"  material="light_blue" class="panda/visual"/>
                  <geom mesh="link6_8"  material="light_blue" class="panda/visual"/>
                  <geom mesh="link6_9"  material="dark_grey"  class="panda/visual"/>
                  <geom mesh="link6_10" material="dark_grey"  class="panda/visual"/>
                  <geom mesh="link6_11" material="white"      class="panda/visual"/>
                  <geom mesh="link6_12" material="green"      class="panda/visual"/>
                  <geom mesh="link6_13" material="white"      class="panda/visual"/>
                  <geom mesh="link6_14" material="dark_grey"  class="panda/visual"/>
                  <geom mesh="link6_15" material="dark_grey"  class="panda/visual"/>
                  <geom mesh="link6_16" material="white"      class="panda/visual"/>
                  <geom mesh="link6_c" class="panda/collision"/>
                  <body name="p1_link7" pos="0.088 0 0" quat="1 1 0 0">
                    <inertial mass="7.35522e-01" pos="1.0517e-2 -4.252e-3 6.1597e-2"
                      fullinertia="1.2516e-2 1.0027e-2 4.815e-3 -4.28e-4 -1.196e-3 -7.41e-4"/>
                    <joint name="p1_joint7"/>
                    <geom mesh="link7_0" material="white"     class="panda/visual"/>
                    <geom mesh="link7_1" material="dark_grey" class="panda/visual"/>
                    <geom mesh="link7_2" material="dark_grey" class="panda/visual"/>
                    <geom mesh="link7_3" material="dark_grey" class="panda/visual"/>
                    <geom mesh="link7_4" material="dark_grey" class="panda/visual"/>
                    <geom mesh="link7_5" material="dark_grey" class="panda/visual"/>
                    <geom mesh="link7_6" material="dark_grey" class="panda/visual"/>
                    <geom mesh="link7_7" material="white"     class="panda/visual"/>
                    <geom mesh="link7_c" class="panda/collision"/>

                    <!-- P1 TDCR (scale=0.125) -->
                      <body name="attachment" pos="0 0 0.107" quat="0.3826834 0 0 0.9238795">
                        <site name="attachment_site"/>
                        <body name="tdcr_platform" pos="0 0 0" euler="0 0 0">
                          <geom type="mesh" mesh="platform_mesh" rgba="0.6 0.6 0.6 1"/>
                          <body name="tdcr_base" pos="0 0.00875 0.0175" euler="-0.524 0 1.57">
                            <geom type="mesh" mesh="base_mesh" rgba="0.3 0.3 0.8 1"/>
                            <site name="b_1" pos="-0.0090625 0 0.0025" size="0.002 0.002 0.002"/>
                            <site name="b_2" pos=" 0.0090625 0 0.0025" size="0.002 0.002 0.002"/>
                          </body>
                          <body name="segment_1" pos="0 0.01575 0.029525" euler="-0.524 3.14159 1.5708">
                            <geom type="mesh" mesh="segment_mesh" rgba="0.9 0.3 0.3 1"/>
                            <joint name="tdcr_Joint1" pos="0 0 0.01075" axis="0 -1 0" limited="true" range="-0.523 0.523" stiffness="0.081647" damping="0.083295"/>
                            <inertial pos="0 0 0" quat="1 0 0 0" mass="0.007602" diaginertia="0.000364 0.000364 0.00045711"/>
                            <site name="s1_1" pos=" 0.008625 0 0.0065625" size="0.002 0.002 0.002"/>
                            <site name="s1_2" pos="-0.008625 0 0.0065625" size="0.002 0.002 0.002"/>
                            <site name="s1_3" pos=" 0.008125 0 0.000625" size="0.002 0.002 0.002"/>
                            <site name="s1_4" pos="-0.008125 0 0.000625" size="0.002 0.002 0.002"/>
                              <body name="segment_2" pos="0 0 -0.009775">
                                <geom type="mesh" mesh="segment_2_mesh" rgba="0.9 0.3 0.3 1"/>
                                <joint name="tdcr_Joint2" pos="0 0 0.009775" axis="0 -1 0" limited="true" range="-0.523 0.523" stiffness="0.034692" damping="0.00693847"/>
                                <inertial pos="0 0 0" quat="1 0 0 0" mass="0.00577752" diaginertia="0.000303212 0.000303212 0.000380773"/>
                                <site name="s2_1" pos=" 0.0079375 0 0.00625" size="0.002 0.002 0.002"/>
                                <site name="s2_2" pos="-0.0079375 0 0.00625" size="0.002 0.002 0.002"/>
                                <site name="s2_3" pos=" 0.0075 0 0.000625" size="0.002 0.002 0.002"/>
                                <site name="s2_4" pos="-0.0075 0 0.000625" size="0.002 0.002 0.002"/>
                                <body name="segment_3" pos="0 0 -0.00891875">
                                  <geom type="mesh" mesh="segment_3_mesh" rgba="0.9 0.3 0.3 1"/>
                                  <joint name="tdcr_Joint3" pos="0 0 0.0089225" axis="0 -1 0" limited="true" range="-0.523 0.523" stiffness="0.0288984" damping="0.00577975"/>
                                  <inertial pos="0 0 0" quat="1 0 0 0" mass="0.00439092" diaginertia="0.000252576 0.000252576 0.000317184"/>
                                  <site name="s3_1" pos=" 0.00725 0 0.005625" size="0.002 0.002 0.002"/>
                                  <site name="s3_2" pos="-0.00725 0 0.005625" size="0.002 0.002 0.002"/>
                                  <site name="s3_3" pos=" 0.006875 0 0.000625" size="0.002 0.002 0.002"/>
                                  <site name="s3_4" pos="-0.006875 0 0.000625" size="0.002 0.002 0.002"/>
                                  <body name="segment_4" pos="0 0 -0.00813875">
                                    <geom type="mesh" mesh="segment_4_mesh" rgba="0.9 0.3 0.3 1"/>
                                    <joint name="tdcr_Joint4" pos="0 0 0.0081720425" axis="0 -1 0" limited="true" range="-0.523 0.523" stiffness="0.0240724" damping="0.00481453"/>
                                    <inertial pos="0 0 0" quat="1 0 0 0" mass="0.0033371" diaginertia="0.000210395 0.000210395 0.000264214"/>
                                    <site name="s4_1" pos=" 0.0065625 0 0.005" size="0.002 0.002 0.002"/>
                                    <site name="s4_2" pos="-0.0065625 0 0.005" size="0.002 0.002 0.002"/>
                                    <site name="s4_3" pos=" 0.00625 0 0.000625" size="0.002 0.002 0.002"/>
                                    <site name="s4_4" pos="-0.00625 0 0.000625" size="0.002 0.002 0.002"/>
                                    <body name="segment_5" pos="0 0 -0.007425">
                                      <geom type="mesh" mesh="segment_5_mesh" rgba="0.9 0.3 0.3 1"/>
                                      <joint name="tdcr_Joint5" pos="0 0 0.00745835" axis="0 -1 0" limited="true" range="-0.523 0.523" stiffness="0.0200523" damping="0.0040105"/>
                                      <inertial pos="0 0 0" quat="1 0 0 0" mass="0.00253619" diaginertia="0.000175259 0.000175259 0.00022009"/>
                                      <site name="s5_1" pos=" 0.0059375 0 0.0046875" size="0.002 0.002 0.002"/>
                                      <site name="s5_2" pos="-0.0059375 0 0.0046875" size="0.002 0.002 0.002"/>
                                      <site name="s5_3" pos=" 0.005625 0 0.000625" size="0.002 0.002 0.002"/>
                                      <site name="s5_4" pos="-0.005625 0 0.000625" size="0.002 0.002 0.002"/>
                                      <body name="segment_6" pos="0 0 -0.006775">
                                        <geom type="mesh" mesh="segment_6_mesh" rgba="0.9 0.3 0.3 1"/>
                                        <joint name="tdcr_Joint6" pos="0 0 0.0068069" axis="0 -1 0" limited="true" range="-0.523 0.523" stiffness="0.0167035" damping="0.00334075"/>
                                        <inertial pos="0 0 0" quat="1 0 0 0" mass="0.00192751" diaginertia="0.000145991 0.000145991 0.000183335"/>
                                        <site name="s6_1" pos=" 0.0053125 0 0.004375" size="0.002 0.002 0.002"/>
                                        <site name="s6_2" pos="-0.0053125 0 0.004375" size="0.002 0.002 0.002"/>
                                        <site name="s6_3" pos=" 0.005 0 0.000625" size="0.002 0.002 0.002"/>
                                        <site name="s6_4" pos="-0.005 0 0.000625" size="0.002 0.002 0.002"/>
                                        <body name="segment_7" pos="0 0 -0.0061875">
                                          <geom type="mesh" mesh="segment_7_mesh" rgba="0.9 0.3 0.3 1"/>
                                          <joint name="tdcr_Joint7" pos="0 0 0.006212425" axis="0 -1 0" limited="true" range="-0.523 0.523" stiffness="0.0139141" damping="0.00278284"/>
                                          <inertial pos="0 0 0" quat="1 0 0 0" mass="0.0014649" diaginertia="0.000121611 0.000121611 0.000152718"/>
                                          <site name="s7_1" pos=" 0.004875 0 0.003875" size="0.002 0.002 0.002"/>
                                          <site name="s7_2" pos="-0.004875 0 0.003875" size="0.002 0.002 0.002"/>
                                          <site name="s7_3" pos=" 0.0045625 0 0.0004125" size="0.002 0.002 0.002"/>
                                          <site name="s7_4" pos="-0.0045625 0 0.0004125" size="0.002 0.002 0.002"/>
                                          <body name="segment_8" pos="0 0 -0.00564375">
                                            <geom type="mesh" mesh="segment_8_mesh" rgba="0.9 0.3 0.3 1"/>
                                            <joint name="tdcr_Joint8" pos="0 0 0.005669765" axis="0 -1 0" limited="true" range="-0.523 0.523" stiffness="0.0115904" damping="0.00231811"/>
                                            <inertial pos="0 0 0" quat="1 0 0 0" mass="0.00111333" diaginertia="0.000101302 0.000101302 0.000127214"/>
                                            <site name="s8_1" pos=" 0.004375 0 0.0036875" size="0.002 0.002 0.002"/>
                                            <site name="s8_2" pos="-0.004375 0 0.0036875" size="0.002 0.002 0.002"/>
                                            <site name="s8_3" pos=" 0.0040875 0 0.000325" size="0.002 0.002 0.002"/>
                                            <site name="s8_4" pos="-0.0040875 0 0.000325" size="0.002 0.002 0.002"/>
                                            <body name="segment_9" pos="0 0 -0.00515">
                                              <geom type="mesh" mesh="segment_9_mesh" rgba="0.9 0.3 0.3 1"/>
                                              <joint name="tdcr_Joint9" pos="0 0 0.0051745125" axis="0 -1 0" limited="true" range="-0.523 0.523" stiffness="0.00965481" damping="0.00193099"/>
                                              <inertial pos="0 0 0" quat="1 0 0 0" mass="0.000846129" diaginertia="8.43843e-05 8.43843e-05 0.000105969"/>
                                              <site name="s9_1" pos=" 0.004025 0 0.00325" size="0.002 0.002 0.002"/>
                                              <site name="s9_2" pos="-0.004025 0 0.00325" size="0.002 0.002 0.002"/>
                                              <site name="s9_3" pos=" 0.00375 0 0.0002375" size="0.002 0.002 0.002"/>
                                              <site name="s9_4" pos="-0.00375 0 0.0002375" size="0.002 0.002 0.002"/>
                                              <body name="segment_10" pos="0 0 -0.0047">
                                                <geom type="mesh" mesh="segment_10_mesh" rgba="0.9 0.3 0.3 1"/>
                                                <joint name="tdcr_Joint10" pos="0 0 0.0047225825" axis="0 -1 0" limited="true" range="-0.523 0.523" stiffness="0.00804246" damping="0.00160851"/>
                                                <inertial pos="0 0 0" quat="1 0 0 0" mass="0.000643058" diaginertia="7.02921e-05 7.02921e-05 8.82726e-05"/>
                                                <site name="s10_1" pos=" 0.003675 0 0.0029375" size="0.002 0.002 0.002"/>
                                                <site name="s10_2" pos="-0.003675 0 0.0029375" size="0.002 0.002 0.002"/>
                                                <site name="s10_3" pos=" 0.00345 0 0.000265" size="0.002 0.002 0.002"/>
                                                <site name="s10_4" pos="-0.00345 0 0.000265" size="0.002 0.002 0.002"/>
                                                <body name="segment_11" pos="0 0 -0.0042875">
                                                  <geom type="mesh" mesh="segment_11_mesh" rgba="0.9 0.3 0.3 1"/>
                                                  <joint name="tdcr_Joint11" pos="0 0 0.004310105" axis="0 -1 0" limited="true" range="-0.523 0.523" stiffness="0.00669937" damping="0.00133989"/>
                                                  <inertial pos="0 0 0" quat="1 0 0 0" mass="0.000488724" diaginertia="5.85533e-05 5.85533e-05 7.3531e-05"/>
                                                  <site name="s11_1" pos=" 0.0035 0 0.0026875" size="0.002 0.002 0.002"/>
                                                  <site name="s11_2" pos="-0.0035 0 0.0026875" size="0.002 0.002 0.002"/>
                                                  <site name="s11_3" pos=" 0.0031125 0 0.00025" size="0.002 0.002 0.002"/>
                                                  <site name="s11_4" pos="-0.0031125 0 0.00025" size="0.002 0.002 0.002"/>
                                                  <body name="segment_12" pos="0 0 -0.0039125">
                                                    <geom type="mesh" mesh="segment_12_mesh" rgba="0.9 0.3 0.3 1"/>
                                                    <joint name="tdcr_Joint12" pos="0 0 0.00393364" axis="0 -1 0" limited="true" range="-0.523 0.523" stiffness="0.00558057" damping="0.00111613"/>
                                                    <inertial pos="0 0 0" quat="1 0 0 0" mass="0.10037143" diaginertia="4.87749e-05 4.87749e-05 6.12514e-05"/>
                                                    <site name="s12_1" pos=" 0.003 0 0.0024625" size="0.002 0.002 0.002"/>
                                                    <site name="s12_2" pos="-0.003 0 0.0024625" size="0.002 0.002 0.002"/>
                                                    <site name="s12_3" pos=" 0.0028125 0 0.00025" size="0.002 0.002 0.002"/>
                                                    <site name="s12_4" pos="-0.0028125 0 0.00025" size="0.002 0.002 0.002"/>
                                                    <body name="tdcr_gripper_base" pos="0 0 0" euler="0 3.14159 0">
                                                      <geom type="mesh" mesh="gripper_base" rgba="0.6 0.6 0.6 1"/>
                                                      <site name="base_1" pos="0 0 0.0025" size="0.002 0.002 0.002"/>
                                                      <body name="gripper_1" pos="0.0028875 0 0.0044375">
                                                        <geom type="mesh" mesh="gripper" rgba="0.9 0.9 0.9 1" friction="2 0.01 0.001"/>
                                                        <joint name="gripper_1_joint" type="hinge" pos="0 0 0" axis="0 1 0" range="-45 0" limited="true" stiffness="5" damping="0.5"/>
                                                        <site name="grip_1" pos="-0.0023125 0 0" size="0.002 0.002 0.002"/>
                                                      </body>
                                                      <body name="gripper_2" pos="-0.0028875 0 0.0044375" euler="0 0 3.14159">
                                                        <geom type="mesh" mesh="gripper" rgba="1 1 1 1" friction="2 0.01 0.001"/>
                                                        <joint name="gripper_2_joint" type="hinge" pos="0 0 0" axis="0 -1 0" range="0 45" limited="true" stiffness="5" damping="0.5"/>
                                                        <site name="grip_2" pos="-0.0023125 0 0" size="0.002 0.002 0.002"/>
                                                      </body>
                                                    </body><!-- gripper_base -->
                                                  </body><!-- segment_12 -->
                                                </body><!-- segment_11 -->
                                              </body><!-- segment_10 -->
                                            </body><!-- segment_9 -->
                                          </body><!-- segment_8 -->
                                        </body><!-- segment_7 -->
                                      </body><!-- segment_6 -->
                                    </body><!-- segment_5 -->
                                  </body><!-- segment_4 -->
                                </body><!-- segment_3 -->
                              </body><!-- segment_2 -->
                            </body><!-- segment_1 -->
                          </body><!-- tdcr_platform -->
                        </body><!-- attachment -->
                  </body><!-- p1_link7 -->
                </body><!-- p1_link6 -->
              </body><!-- p1_link5 -->
            </body><!-- p1_link4 -->
          </body><!-- p1_link3 -->
        </body><!-- p1_link2 -->
      </body><!-- p1_link1 -->
    </body><!-- p1_link0 -->

    <!-- ══════════════════════════════════════════════════════
         PANDA 2  –  right (x=+0.55), facing +Y — PANDA UNSCALED
    ═══════════════════════════════════════════════════════════ -->
    <body name="p2_link0" childclass="panda" pos="0.55 0 0.2" euler="0 0 1.5708">
      <inertial mass="0.629769" pos="-0.041018 -0.00014 0.049974"
        fullinertia="0.00315 0.00388 0.004285 8.2904e-7 0.00015 8.2299e-6"/>
      <geom mesh="link0_0"  material="off_white"  class="panda/visual"/>
      <geom mesh="link0_1"  material="dark_grey"  class="panda/visual"/>
      <geom mesh="link0_2"  material="off_white"  class="panda/visual"/>
      <geom mesh="link0_3"  material="dark_grey"  class="panda/visual"/>
      <geom mesh="link0_4"  material="off_white"  class="panda/visual"/>
      <geom mesh="link0_5"  material="dark_grey"  class="panda/visual"/>
      <geom mesh="link0_7"  material="white"      class="panda/visual"/>
      <geom mesh="link0_8"  material="white"      class="panda/visual"/>
      <geom mesh="link0_9"  material="dark_grey"  class="panda/visual"/>
      <geom mesh="link0_10" material="off_white"  class="panda/visual"/>
      <geom mesh="link0_11" material="white"      class="panda/visual"/>
      <geom mesh="link0_c"  class="panda/collision"/>
      <body name="p2_link1" pos="0 0 0.333">
        <inertial mass="4.970684" pos="0.003875 0.002081 -0.04762"
          fullinertia="0.70337 0.70661 0.0091170 -0.00013900 0.0067720 0.019169"/>
        <joint name="p2_joint1"/>
        <geom material="white" mesh="link1" class="panda/visual"/>
        <geom mesh="link1_c" class="panda/collision"/>
        <body name="p2_link2" quat="1 -1 0 0">
          <inertial mass="0.646926" pos="-0.003141 -0.02872 0.003495"
            fullinertia="0.0079620 2.8110e-2 2.5995e-2 -3.925e-3 1.0254e-2 7.04e-4"/>
          <joint name="p2_joint2" range="-1.7628 1.7628"/>
          <geom material="white" mesh="link2" class="panda/visual"/>
          <geom mesh="link2_c" class="panda/collision"/>
          <body name="p2_link3" pos="0 -0.316 0" quat="1 1 0 0">
            <joint name="p2_joint3"/>
            <inertial mass="3.228604" pos="2.7518e-2 3.9252e-2 -6.6502e-2"
              fullinertia="3.7242e-2 3.6155e-2 1.083e-2 -4.761e-3 -1.1396e-2 -1.2805e-2"/>
            <geom mesh="link3_0" material="white"     class="panda/visual"/>
            <geom mesh="link3_1" material="white"     class="panda/visual"/>
            <geom mesh="link3_2" material="white"     class="panda/visual"/>
            <geom mesh="link3_3" material="dark_grey" class="panda/visual"/>
            <geom mesh="link3_c" class="panda/collision"/>
            <body name="p2_link4" pos="0.0825 0 0" quat="1 1 0 0">
              <inertial mass="3.587895" pos="-5.317e-2 1.04419e-1 2.7454e-2"
                fullinertia="2.5853e-2 1.9552e-2 2.8323e-2 7.796e-3 -1.332e-3 8.641e-3"/>
              <joint name="p2_joint4" range="-3.0718 -0.0698"/>
              <geom mesh="link4_0" material="white"     class="panda/visual"/>
              <geom mesh="link4_1" material="white"     class="panda/visual"/>
              <geom mesh="link4_2" material="dark_grey" class="panda/visual"/>
              <geom mesh="link4_3" material="white"     class="panda/visual"/>
              <geom mesh="link4_c" class="panda/collision"/>
              <body name="p2_link5" pos="-0.0825 0.384 0" quat="1 -1 0 0">
                <inertial mass="1.225946" pos="-1.1953e-2 4.1065e-2 -3.8437e-2"
                  fullinertia="3.5549e-2 2.9474e-2 8.627e-3 -2.117e-3 -4.037e-3 2.29e-4"/>
                <joint name="p2_joint5"/>
                <geom mesh="link5_0" material="dark_grey" class="panda/visual"/>
                <geom mesh="link5_1" material="white"     class="panda/visual"/>
                <geom mesh="link5_2" material="white"     class="panda/visual"/>
                <geom mesh="link5_c0" class="panda/collision"/>
                <geom mesh="link5_c1" class="panda/collision"/>
                <geom mesh="link5_c2" class="panda/collision"/>
                <body name="p2_link6" quat="1 1 0 0">
                  <inertial mass="1.666555" pos="6.0149e-2 -1.4117e-2 -1.0517e-2"
                    fullinertia="1.964e-3 4.354e-3 5.433e-3 1.09e-4 -1.158e-3 3.41e-4"/>
                  <joint name="p2_joint6" range="-0.0175 3.7525"/>
                  <geom mesh="link6_0"  material="off_white"  class="panda/visual"/>
                  <geom mesh="link6_1"  material="white"      class="panda/visual"/>
                  <geom mesh="link6_2"  material="dark_grey"  class="panda/visual"/>
                  <geom mesh="link6_3"  material="white"      class="panda/visual"/>
                  <geom mesh="link6_4"  material="white"      class="panda/visual"/>
                  <geom mesh="link6_5"  material="white"      class="panda/visual"/>
                  <geom mesh="link6_6"  material="white"      class="panda/visual"/>
                  <geom mesh="link6_7"  material="light_blue" class="panda/visual"/>
                  <geom mesh="link6_8"  material="light_blue" class="panda/visual"/>
                  <geom mesh="link6_9"  material="dark_grey"  class="panda/visual"/>
                  <geom mesh="link6_10" material="dark_grey"  class="panda/visual"/>
                  <geom mesh="link6_11" material="white"      class="panda/visual"/>
                  <geom mesh="link6_12" material="green"      class="panda/visual"/>
                  <geom mesh="link6_13" material="white"      class="panda/visual"/>
                  <geom mesh="link6_14" material="dark_grey"  class="panda/visual"/>
                  <geom mesh="link6_15" material="dark_grey"  class="panda/visual"/>
                  <geom mesh="link6_16" material="white"      class="panda/visual"/>
                  <geom mesh="link6_c" class="panda/collision"/>
                  <body name="p2_link7" pos="0.088 0 0" quat="1 1 0 0">
                    <inertial mass="7.35522e-01" pos="1.0517e-2 -4.252e-3 6.1597e-2"
                      fullinertia="1.2516e-2 1.0027e-2 4.815e-3 -4.28e-4 -1.196e-3 -7.41e-4"/>
                    <joint name="p2_joint7"/>
                    <geom mesh="link7_0" material="white"     class="panda/visual"/>
                    <geom mesh="link7_1" material="dark_grey" class="panda/visual"/>
                    <geom mesh="link7_2" material="dark_grey" class="panda/visual"/>
                    <geom mesh="link7_3" material="dark_grey" class="panda/visual"/>
                    <geom mesh="link7_4" material="dark_grey" class="panda/visual"/>
                    <geom mesh="link7_5" material="dark_grey" class="panda/visual"/>
                    <geom mesh="link7_6" material="dark_grey" class="panda/visual"/>
                    <geom mesh="link7_7" material="white"     class="panda/visual"/>
                    <geom mesh="link7_c" class="panda/collision"/>

                    <!-- P2 TDCR (scale=0.125) -->
                      <body name="p2_attachment" pos="0 0 0.107" quat="0.3826834 0 0 0.9238795">
                        <site name="p2_attachment_site"/>
                        <body name="p2_tdcr_platform" pos="0 0 0" euler="0 0 0">
                          <geom type="mesh" mesh="platform_mesh" rgba="0.6 0.6 0.6 1"/>
                          <body name="p2_tdcr_base" pos="0 0.00875 0.0175" euler="-0.524 0 1.57">
                            <geom type="mesh" mesh="base_mesh" rgba="0.3 0.3 0.8 1"/>
                            <site name="p2_b_1" pos="-0.0090625 0 0.0025" size="0.002 0.002 0.002"/>
                            <site name="p2_b_2" pos=" 0.0090625 0 0.0025" size="0.002 0.002 0.002"/>
                          </body>
                          <body name="p2_segment_1" pos="0 0.01575 0.029525" euler="-0.524 3.14159 1.5708">
                            <geom type="mesh" mesh="segment_mesh" rgba="0.9 0.3 0.3 1"/>
                            <joint name="p2_tdcr_Joint1" pos="0 0 0.01075" axis="0 -1 0" limited="true" range="-0.523 0.523" stiffness="0.081647" damping="0.083295"/>
                            <inertial pos="0 0 0" quat="1 0 0 0" mass="0.007602" diaginertia="0.000364 0.000364 0.00045711"/>
                            <site name="p2_s1_1" pos=" 0.008625 0 0.0065625" size="0.002 0.002 0.002"/>
                            <site name="p2_s1_2" pos="-0.008625 0 0.0065625" size="0.002 0.002 0.002"/>
                            <site name="p2_s1_3" pos=" 0.008125 0 0.000625" size="0.002 0.002 0.002"/>
                            <site name="p2_s1_4" pos="-0.008125 0 0.000625" size="0.002 0.002 0.002"/>
                              <body name="p2_segment_2" pos="0 0 -0.009775">
                                <geom type="mesh" mesh="segment_2_mesh" rgba="0.9 0.3 0.3 1"/>
                                <joint name="p2_tdcr_Joint2" pos="0 0 0.009775" axis="0 -1 0" limited="true" range="-0.523 0.523" stiffness="0.034692" damping="0.00693847"/>
                                <inertial pos="0 0 0" quat="1 0 0 0" mass="0.00577752" diaginertia="0.000303212 0.000303212 0.000380773"/>
                                <site name="p2_s2_1" pos=" 0.0079375 0 0.00625" size="0.002 0.002 0.002"/>
                                <site name="p2_s2_2" pos="-0.0079375 0 0.00625" size="0.002 0.002 0.002"/>
                                <site name="p2_s2_3" pos=" 0.0075 0 0.000625" size="0.002 0.002 0.002"/>
                                <site name="p2_s2_4" pos="-0.0075 0 0.000625" size="0.002 0.002 0.002"/>
                                <body name="p2_segment_3" pos="0 0 -0.00891875">
                                  <geom type="mesh" mesh="segment_3_mesh" rgba="0.9 0.3 0.3 1"/>
                                  <joint name="p2_tdcr_Joint3" pos="0 0 0.0089225" axis="0 -1 0" limited="true" range="-0.523 0.523" stiffness="0.0288984" damping="0.00577975"/>
                                  <inertial pos="0 0 0" quat="1 0 0 0" mass="0.00439092" diaginertia="0.000252576 0.000252576 0.000317184"/>
                                  <site name="p2_s3_1" pos=" 0.00725 0 0.005625" size="0.002 0.002 0.002"/>
                                  <site name="p2_s3_2" pos="-0.00725 0 0.005625" size="0.002 0.002 0.002"/>
                                  <site name="p2_s3_3" pos=" 0.006875 0 0.000625" size="0.002 0.002 0.002"/>
                                  <site name="p2_s3_4" pos="-0.006875 0 0.000625" size="0.002 0.002 0.002"/>
                                  <body name="p2_segment_4" pos="0 0 -0.00813875">
                                    <geom type="mesh" mesh="segment_4_mesh" rgba="0.9 0.3 0.3 1"/>
                                    <joint name="p2_tdcr_Joint4" pos="0 0 0.0081720425" axis="0 -1 0" limited="true" range="-0.523 0.523" stiffness="0.0240724" damping="0.00481453"/>
                                    <inertial pos="0 0 0" quat="1 0 0 0" mass="0.0033371" diaginertia="0.000210395 0.000210395 0.000264214"/>
                                    <site name="p2_s4_1" pos=" 0.0065625 0 0.005" size="0.002 0.002 0.002"/>
                                    <site name="p2_s4_2" pos="-0.0065625 0 0.005" size="0.002 0.002 0.002"/>
                                    <site name="p2_s4_3" pos=" 0.00625 0 0.000625" size="0.002 0.002 0.002"/>
                                    <site name="p2_s4_4" pos="-0.00625 0 0.000625" size="0.002 0.002 0.002"/>
                                    <body name="p2_segment_5" pos="0 0 -0.007425">
                                      <geom type="mesh" mesh="segment_5_mesh" rgba="0.9 0.3 0.3 1"/>
                                      <joint name="p2_tdcr_Joint5" pos="0 0 0.00745835" axis="0 -1 0" limited="true" range="-0.523 0.523" stiffness="0.0200523" damping="0.0040105"/>
                                      <inertial pos="0 0 0" quat="1 0 0 0" mass="0.00253619" diaginertia="0.000175259 0.000175259 0.00022009"/>
                                      <site name="p2_s5_1" pos=" 0.0059375 0 0.0046875" size="0.002 0.002 0.002"/>
                                      <site name="p2_s5_2" pos="-0.0059375 0 0.0046875" size="0.002 0.002 0.002"/>
                                      <site name="p2_s5_3" pos=" 0.005625 0 0.000625" size="0.002 0.002 0.002"/>
                                      <site name="p2_s5_4" pos="-0.005625 0 0.000625" size="0.002 0.002 0.002"/>
                                      <body name="p2_segment_6" pos="0 0 -0.006775">
                                        <geom type="mesh" mesh="segment_6_mesh" rgba="0.9 0.3 0.3 1"/>
                                        <joint name="p2_tdcr_Joint6" pos="0 0 0.0068069" axis="0 -1 0" limited="true" range="-0.523 0.523" stiffness="0.0167035" damping="0.00334075"/>
                                        <inertial pos="0 0 0" quat="1 0 0 0" mass="0.00192751" diaginertia="0.000145991 0.000145991 0.000183335"/>
                                        <site name="p2_s6_1" pos=" 0.0053125 0 0.004375" size="0.002 0.002 0.002"/>
                                        <site name="p2_s6_2" pos="-0.0053125 0 0.004375" size="0.002 0.002 0.002"/>
                                        <site name="p2_s6_3" pos=" 0.005 0 0.000625" size="0.002 0.002 0.002"/>
                                        <site name="p2_s6_4" pos="-0.005 0 0.000625" size="0.002 0.002 0.002"/>
                                        <body name="p2_segment_7" pos="0 0 -0.0061875">
                                          <geom type="mesh" mesh="segment_7_mesh" rgba="0.9 0.3 0.3 1"/>
                                          <joint name="p2_tdcr_Joint7" pos="0 0 0.006212425" axis="0 -1 0" limited="true" range="-0.523 0.523" stiffness="0.0139141" damping="0.00278284"/>
                                          <inertial pos="0 0 0" quat="1 0 0 0" mass="0.0014649" diaginertia="0.000121611 0.000121611 0.000152718"/>
                                          <site name="p2_s7_1" pos=" 0.004875 0 0.003875" size="0.002 0.002 0.002"/>
                                          <site name="p2_s7_2" pos="-0.004875 0 0.003875" size="0.002 0.002 0.002"/>
                                          <site name="p2_s7_3" pos=" 0.0045625 0 0.0004125" size="0.002 0.002 0.002"/>
                                          <site name="p2_s7_4" pos="-0.0045625 0 0.0004125" size="0.002 0.002 0.002"/>
                                          <body name="p2_segment_8" pos="0 0 -0.00564375">
                                            <geom type="mesh" mesh="segment_8_mesh" rgba="0.9 0.3 0.3 1"/>
                                            <joint name="p2_tdcr_Joint8" pos="0 0 0.005669765" axis="0 -1 0" limited="true" range="-0.523 0.523" stiffness="0.0115904" damping="0.00231811"/>
                                            <inertial pos="0 0 0" quat="1 0 0 0" mass="0.00111333" diaginertia="0.000101302 0.000101302 0.000127214"/>
                                            <site name="p2_s8_1" pos=" 0.004375 0 0.0036875" size="0.002 0.002 0.002"/>
                                            <site name="p2_s8_2" pos="-0.004375 0 0.0036875" size="0.002 0.002 0.002"/>
                                            <site name="p2_s8_3" pos=" 0.0040875 0 0.000325" size="0.002 0.002 0.002"/>
                                            <site name="p2_s8_4" pos="-0.0040875 0 0.000325" size="0.002 0.002 0.002"/>
                                            <body name="p2_segment_9" pos="0 0 -0.00515">
                                              <geom type="mesh" mesh="segment_9_mesh" rgba="0.9 0.3 0.3 1"/>
                                              <joint name="p2_tdcr_Joint9" pos="0 0 0.0051745125" axis="0 -1 0" limited="true" range="-0.523 0.523" stiffness="0.00965481" damping="0.00193099"/>
                                              <inertial pos="0 0 0" quat="1 0 0 0" mass="0.000846129" diaginertia="8.43843e-05 8.43843e-05 0.000105969"/>
                                              <site name="p2_s9_1" pos=" 0.004025 0 0.00325" size="0.002 0.002 0.002"/>
                                              <site name="p2_s9_2" pos="-0.004025 0 0.00325" size="0.002 0.002 0.002"/>
                                              <site name="p2_s9_3" pos=" 0.00375 0 0.0002375" size="0.002 0.002 0.002"/>
                                              <site name="p2_s9_4" pos="-0.00375 0 0.0002375" size="0.002 0.002 0.002"/>
                                              <body name="p2_segment_10" pos="0 0 -0.0047">
                                                <geom type="mesh" mesh="segment_10_mesh" rgba="0.9 0.3 0.3 1"/>
                                                <joint name="p2_tdcr_Joint10" pos="0 0 0.0047225825" axis="0 -1 0" limited="true" range="-0.523 0.523" stiffness="0.00804246" damping="0.00160851"/>
                                                <inertial pos="0 0 0" quat="1 0 0 0" mass="0.000643058" diaginertia="7.02921e-05 7.02921e-05 8.82726e-05"/>
                                                <site name="p2_s10_1" pos=" 0.003675 0 0.0029375" size="0.002 0.002 0.002"/>
                                                <site name="p2_s10_2" pos="-0.003675 0 0.0029375" size="0.002 0.002 0.002"/>
                                                <site name="p2_s10_3" pos=" 0.00345 0 0.000265" size="0.002 0.002 0.002"/>
                                                <site name="p2_s10_4" pos="-0.00345 0 0.000265" size="0.002 0.002 0.002"/>
                                                <body name="p2_segment_11" pos="0 0 -0.0042875">
                                                  <geom type="mesh" mesh="segment_11_mesh" rgba="0.9 0.3 0.3 1"/>
                                                  <joint name="p2_tdcr_Joint11" pos="0 0 0.004310105" axis="0 -1 0" limited="true" range="-0.523 0.523" stiffness="0.00669937" damping="0.00133989"/>
                                                  <inertial pos="0 0 0" quat="1 0 0 0" mass="0.000488724" diaginertia="5.85533e-05 5.85533e-05 7.3531e-05"/>
                                                  <site name="p2_s11_1" pos=" 0.0035 0 0.0026875" size="0.002 0.002 0.002"/>
                                                  <site name="p2_s11_2" pos="-0.0035 0 0.0026875" size="0.002 0.002 0.002"/>
                                                  <site name="p2_s11_3" pos=" 0.0031125 0 0.00025" size="0.002 0.002 0.002"/>
                                                  <site name="p2_s11_4" pos="-0.0031125 0 0.00025" size="0.002 0.002 0.002"/>
                                                  <body name="p2_segment_12" pos="0 0 -0.0039125">
                                                    <geom type="mesh" mesh="segment_12_mesh" rgba="0.9 0.3 0.3 1"/>
                                                    <joint name="p2_tdcr_Joint12" pos="0 0 0.00393364" axis="0 -1 0" limited="true" range="-0.523 0.523" stiffness="0.00558057" damping="0.00111613"/>
                                                    <inertial pos="0 0 0" quat="1 0 0 0" mass="0.10037143" diaginertia="4.87749e-05 4.87749e-05 6.12514e-05"/>
                                                    <site name="p2_s12_1" pos=" 0.003 0 0.0024625" size="0.002 0.002 0.002"/>
                                                    <site name="p2_s12_2" pos="-0.003 0 0.0024625" size="0.002 0.002 0.002"/>
                                                    <site name="p2_s12_3" pos=" 0.0028125 0 0.00025" size="0.002 0.002 0.002"/>
                                                    <site name="p2_s12_4" pos="-0.0028125 0 0.00025" size="0.002 0.002 0.002"/>
                                                    <body name="p2_tdcr_gripper_base" pos="0 0 0" euler="0 3.14159 0">
                                                      <geom type="mesh" mesh="gripper_base" rgba="0.6 0.6 0.6 1"/>
                                                      <site name="p2_base_1" pos="0 0 0.0025" size="0.002 0.002 0.002"/>
                                                      <body name="p2_gripper_1" pos="0.0028875 0 0.0044375">
                                                        <geom type="mesh" mesh="gripper" rgba="0.9 0.9 0.9 1" friction="2 0.01 0.001"/>
                                                        <joint name="p2_gripper_1_joint" type="hinge" pos="0 0 0" axis="0 1 0" range="-45 0" limited="true" stiffness="5" damping="0.5"/>
                                                        <site name="p2_grip_1" pos="-0.0023125 0 0" size="0.002 0.002 0.002"/>
                                                      </body>
                                                      <body name="p2_gripper_2" pos="-0.0028875 0 0.0044375" euler="0 0 3.14159">
                                                        <geom type="mesh" mesh="gripper" rgba="1 1 1 1" friction="2 0.01 0.001"/>
                                                        <joint name="p2_gripper_2_joint" type="hinge" pos="0 0 0" axis="0 -1 0" range="0 45" limited="true" stiffness="5" damping="0.5"/>
                                                        <site name="p2_grip_2" pos="-0.0023125 0 0" size="0.002 0.002 0.002"/>
                                                      </body>
                                                    </body><!-- gripper_base -->
                                                  </body><!-- p2_segment_12 -->
                                                </body><!-- p2_segment_11 -->
                                              </body><!-- p2_segment_10 -->
                                            </body><!-- p2_segment_9 -->
                                          </body><!-- p2_segment_8 -->
                                        </body><!-- p2_segment_7 -->
                                      </body><!-- p2_segment_6 -->
                                    </body><!-- p2_segment_5 -->
                                  </body><!-- p2_segment_4 -->
                                </body><!-- p2_segment_3 -->
                              </body><!-- p2_segment_2 -->
                            </body><!-- p2_segment_1 -->
                          </body><!-- p2_tdcr_platform -->
                        </body><!-- p2_attachment -->
                  </body><!-- p2_link7 -->
                </body><!-- p2_link6 -->
              </body><!-- p2_link5 -->
            </body><!-- p2_link4 -->
          </body><!-- p2_link3 -->
        </body><!-- p2_link2 -->
      </body><!-- p2_link1 -->
    </body><!-- p2_link0 -->

  </worldbody>

  <!-- ═══════════════════════════════════════════════
       TENDONS
       Tendon ranges scaled by 0.125:
         arm:     0.5–2.0 → 0.0625–0.25
         gripper: 0.009–0.0166 → 0.001125–0.002075
  ════════════════════════════════════════════════════ -->
  <tendon>
    <!-- P1 TDCR arm tendon 1 -->
    <spatial name="t1" width="0.0004" frictionloss="0.1" rgba=".95 .3 .3 1" limited="true" range="0.0625 0.25">
      <site site="b_2"/>
      <site site="s1_1"/>  <site site="s1_3"/>
      <site site="s2_1"/>  <site site="s2_3"/>
      <site site="s3_1"/>  <site site="s3_3"/>
      <site site="s4_1"/>  <site site="s4_3"/>
      <site site="s5_1"/>  <site site="s5_3"/>
      <site site="s6_1"/>  <site site="s6_3"/>
      <site site="s7_1"/>  <site site="s7_3"/>
      <site site="s8_1"/>  <site site="s8_3"/>
      <site site="s9_1"/>  <site site="s9_3"/>
      <site site="s10_1"/>  <site site="s10_3"/>
      <site site="s11_1"/>  <site site="s11_3"/>
      <site site="s12_1"/>  <site site="s12_3"/>
    </spatial>
    <!-- P1 TDCR arm tendon 2 -->
    <spatial name="t2" width="0.0004" frictionloss="0.1" rgba=".95 .3 .3 1" limited="true" range="0.0625 0.25">
      <site site="b_1"/>
      <site site="s1_2"/>  <site site="s1_4"/>
      <site site="s2_2"/>  <site site="s2_4"/>
      <site site="s3_2"/>  <site site="s3_4"/>
      <site site="s4_2"/>  <site site="s4_4"/>
      <site site="s5_2"/>  <site site="s5_4"/>
      <site site="s6_2"/>  <site site="s6_4"/>
      <site site="s7_2"/>  <site site="s7_4"/>
      <site site="s8_2"/>  <site site="s8_4"/>
      <site site="s9_2"/>  <site site="s9_4"/>
      <site site="s10_2"/>  <site site="s10_4"/>
      <site site="s11_2"/>  <site site="s11_4"/>
      <site site="s12_2"/>  <site site="s12_4"/>
    </spatial>
    <!-- P1 gripper tendons -->
    <spatial name="g1" width="0.0004" frictionloss="0.1" rgba=".95 .3 .3 1" limited="true" range="0.001125 0.002075">
      <site site="base_1"/>
      <site site="grip_1"/>
    </spatial>
    <spatial name="g2" width="0.0004" frictionloss="0.1" rgba=".95 .3 .3 1" limited="true" range="0.001125 0.002075">
      <site site="base_1"/>
      <site site="grip_2"/>
    </spatial>

    <!-- P2 TDCR arm tendon 1 -->
    <spatial name="p2_t1" width="0.0004" frictionloss="0.1" rgba=".3 .3 .95 1" limited="true" range="0.0625 0.25">
      <site site="p2_b_2"/>
      <site site="p2_s1_1"/>  <site site="p2_s1_3"/>
      <site site="p2_s2_1"/>  <site site="p2_s2_3"/>
      <site site="p2_s3_1"/>  <site site="p2_s3_3"/>
      <site site="p2_s4_1"/>  <site site="p2_s4_3"/>
      <site site="p2_s5_1"/>  <site site="p2_s5_3"/>
      <site site="p2_s6_1"/>  <site site="p2_s6_3"/>
      <site site="p2_s7_1"/>  <site site="p2_s7_3"/>
      <site site="p2_s8_1"/>  <site site="p2_s8_3"/>
      <site site="p2_s9_1"/>  <site site="p2_s9_3"/>
      <site site="p2_s10_1"/>  <site site="p2_s10_3"/>
      <site site="p2_s11_1"/>  <site site="p2_s11_3"/>
      <site site="p2_s12_1"/>  <site site="p2_s12_3"/>
    </spatial>
    <!-- P2 TDCR arm tendon 2 -->
    <spatial name="p2_t2" width="0.0004" frictionloss="0.1" rgba=".3 .3 .95 1" limited="true" range="0.0625 0.25">
      <site site="p2_b_1"/>
      <site site="p2_s1_2"/>  <site site="p2_s1_4"/>
      <site site="p2_s2_2"/>  <site site="p2_s2_4"/>
      <site site="p2_s3_2"/>  <site site="p2_s3_4"/>
      <site site="p2_s4_2"/>  <site site="p2_s4_4"/>
      <site site="p2_s5_2"/>  <site site="p2_s5_4"/>
      <site site="p2_s6_2"/>  <site site="p2_s6_4"/>
      <site site="p2_s7_2"/>  <site site="p2_s7_4"/>
      <site site="p2_s8_2"/>  <site site="p2_s8_4"/>
      <site site="p2_s9_2"/>  <site site="p2_s9_4"/>
      <site site="p2_s10_2"/>  <site site="p2_s10_4"/>
      <site site="p2_s11_2"/>  <site site="p2_s11_4"/>
      <site site="p2_s12_2"/>  <site site="p2_s12_4"/>
    </spatial>
    <!-- P2 gripper tendons -->
    <spatial name="p2_g1" width="0.0004" frictionloss="0.1" rgba=".3 .3 .95 1" limited="true" range="0.001125 0.002075">
      <site site="p2_base_1"/>
      <site site="p2_grip_1"/>
    </spatial>
    <spatial name="p2_g2" width="0.0004" frictionloss="0.1" rgba=".3 .3 .95 1" limited="true" range="0.001125 0.002075">
      <site site="p2_base_1"/>
      <site site="p2_grip_2"/>
    </spatial>
  </tendon>

  <!-- ═══════════════════════════════════════════════
       ACTUATORS
       Muscle lengthrange scaled by 0.125:
         arm:     0.5–2.0 → 0.0625–0.25
         gripper: 0.009–0.0166 → 0.001125–0.002075
  ════════════════════════════════════════════════════ -->
  <actuator>
    <!-- Panda 1 — UNSCALED -->
    <general class="panda" name="p1_actuator1" joint="p1_joint1" gainprm="4500" biasprm="0 -4500 -450"/>
    <general class="panda" name="p1_actuator2" joint="p1_joint2" gainprm="4500" biasprm="0 -4500 -450" ctrlrange="-1.7628 1.7628"/>
    <general class="panda" name="p1_actuator3" joint="p1_joint3" gainprm="3500" biasprm="0 -3500 -350"/>
    <general class="panda" name="p1_actuator4" joint="p1_joint4" gainprm="3500" biasprm="0 -3500 -350" ctrlrange="-3.0718 -0.0698"/>
    <general class="panda" name="p1_actuator5" joint="p1_joint5" gainprm="2000" biasprm="0 -2000 -200" forcerange="-12 12"/>
    <general class="panda" name="p1_actuator6" joint="p1_joint6" gainprm="2000" biasprm="0 -2000 -200" forcerange="-12 12" ctrlrange="-0.0175 3.7525"/>
    <general class="panda" name="p1_actuator7" joint="p1_joint7" gainprm="2000" biasprm="0 -2000 -200" forcerange="-12 12"/>
    <!-- Panda 2 — UNSCALED -->
    <general class="panda" name="p2_actuator1" joint="p2_joint1" gainprm="4500" biasprm="0 -4500 -450"/>
    <general class="panda" name="p2_actuator2" joint="p2_joint2" gainprm="4500" biasprm="0 -4500 -450" ctrlrange="-1.7628 1.7628"/>
    <general class="panda" name="p2_actuator3" joint="p2_joint3" gainprm="3500" biasprm="0 -3500 -350"/>
    <general class="panda" name="p2_actuator4" joint="p2_joint4" gainprm="3500" biasprm="0 -3500 -350" ctrlrange="-3.0718 -0.0698"/>
    <general class="panda" name="p2_actuator5" joint="p2_joint5" gainprm="2000" biasprm="0 -2000 -200" forcerange="-12 12"/>
    <general class="panda" name="p2_actuator6" joint="p2_joint6" gainprm="2000" biasprm="0 -2000 -200" forcerange="-12 12" ctrlrange="-0.0175 3.7525"/>
    <general class="panda" name="p2_actuator7" joint="p2_joint7" gainprm="2000" biasprm="0 -2000 -200" forcerange="-12 12"/>
    <!-- P1 TDCR muscles — lengthrange scaled -->
    <muscle name="A_1" ctrllimited="true" lengthrange="0.0625 0.25"  ctrlrange="0 1" force="2"     tendon="t1"/>
    <muscle name="A_2" ctrllimited="true" lengthrange="0.0625 0.25"  ctrlrange="0 1" force="2"     tendon="t2"/>
    <muscle name="A_3" ctrllimited="true" lengthrange="0.001125 0.002075" ctrlrange="0 1" force="300.5" tendon="g1"/>
    <muscle name="A_4" ctrllimited="true" lengthrange="0.001125 0.002075" ctrlrange="0 1" force="300.5" tendon="g2"/>
    <!-- P2 TDCR muscles — lengthrange scaled -->
    <muscle name="B_1" ctrllimited="true" lengthrange="0.0625 0.25"  ctrlrange="0 1" force="2"     tendon="p2_t1"/>
    <muscle name="B_2" ctrllimited="true" lengthrange="0.0625 0.25"  ctrlrange="0 1" force="2"     tendon="p2_t2"/>
    <muscle name="B_3" ctrllimited="true" lengthrange="0.001125 0.002075" ctrlrange="0 1" force="300.5" tendon="p2_g1"/>
    <muscle name="B_4" ctrllimited="true" lengthrange="0.001125 0.002075" ctrlrange="0 1" force="300.5" tendon="p2_g2"/>
  </actuator>

  <!-- ═══════════════════════════════════════════════
       CONTACT EXCLUSIONS
  ════════════════════════════════════════════════════ -->
  <contact>
    <exclude body1="p1_link0" body2="p1_link1"/>
    <exclude body1="p2_link0" body2="p2_link1"/>
  </contact>

  <!-- ═══════════════════════════════════════════════
       KEYFRAME
       qpos: 7 (p1 arm) + 7 (p2 arm)
             + 12 (P1 TDCR) + 2 (P1 gripper)
             + 12 (P2 TDCR) + 2 (P2 gripper) = 42
       ctrl: 7 (p1) + 7 (p2) + 4 (P1 TDCR) + 4 (P2 TDCR) = 22
  ════════════════════════════════════════════════════ -->
  <keyframe>
    <key name="home"
      qpos="0 0 0 -1.57079 0 1.57079 -0.7853
            0 0 0 -1.57079 0 1.57079 -0.7853
            0 0 0 0 0 0 0 0 0 0 0 0 0 0
            0 0 0 0 0 0 0 0 0 0 0 0 0 0"
      ctrl="0 0 0 -1.57079 0 1.57079 -0.7853
            0 0 0 -1.57079 0 1.57079 -0.7853
            0 0 0 0
            0 0 0 0"/>
  </keyframe>

</mujoco>
