<mujoco model="two_pandas_nohand_scene">
  <compiler angle="radian" meshdir="assets" autolimits="true"/>
  <option integrator="implicitfast" impratio="10"/>

  <statistic center="0 0 0.6" extent="1.8"/>

  <visual>
    <headlight diffuse="0.6 0.6 0.6" ambient="0.3 0.3 0.3" specular="0 0 0"/>
    <rgba haze="0.15 0.25 0.35 1"/>
    <global azimuth="120" elevation="-20"/>
  </visual>

  <!-- ═══════════════════════════════════════════════
       DEFAULTS  (matches panda nohand exactly)
  ════════════════════════════════════════════════════ -->
  <default>
    <default class="panda">
      <material specular="0.5" shininess="0.25"/>
      <joint armature="0.1" damping="1" axis="0 0 1" range="-2.8973 2.8973"/>
      <general dyntype="none" biastype="affine" ctrlrange="-2.8973 2.8973" forcerange="-87 87"/>
      <default class="panda/visual">
        <geom type="mesh" contype="0" conaffinity="0" group="2"/>
      </default>
      <default class="panda/collision">
        <geom type="mesh" group="3"/>
      </default>
      <site size="0.001" rgba="0.5 0.5 0.5 0.3" group="4"/>
    </default>
  </default>

  <!-- ═══════════════════════════════════════════════
       ASSETS
  ════════════════════════════════════════════════════ -->
  <asset>
    <texture type="skybox" builtin="gradient" rgb1="0.3 0.5 0.7" rgb2="0 0 0" width="512" height="3072"/>
    <texture type="2d" name="groundplane" builtin="checker" mark="edge"
      rgb1="0.2 0.3 0.4" rgb2="0.1 0.2 0.3" markrgb="0.8 0.8 0.8" width="300" height="300"/>
    <material name="groundplane" texture="groundplane" texuniform="true" texrepeat="5 5" reflectance="0.2"/>
    <material name="base_mat" rgba="0.25 0.25 0.28 1" reflectance="0.3"/>
    <material name="pole_mat" rgba="0.55 0.55 0.60 1" reflectance="0.5"/>

    <!-- panda materials -->
    <material class="panda" name="white"      rgba="1 1 1 1"/>
    <material class="panda" name="off_white"  rgba="0.901961 0.921569 0.929412 1"/>
    <material class="panda" name="dark_grey"  rgba="0.25 0.25 0.25 1"/>
    <material class="panda" name="green"      rgba="0 1 0 1"/>
    <material class="panda" name="light_blue" rgba="0.039216 0.541176 0.780392 1"/>

    <!-- collision meshes -->
    <mesh name="link0_c"  file="link0.stl"/>
    <mesh name="link1_c"  file="link1.stl"/>
    <mesh name="link2_c"  file="link2.stl"/>
    <mesh name="link3_c"  file="link3.stl"/>
    <mesh name="link4_c"  file="link4.stl"/>
    <mesh name="link5_c0" file="link5_collision_0.obj"/>
    <mesh name="link5_c1" file="link5_collision_1.obj"/>
    <mesh name="link5_c2" file="link5_collision_2.obj"/>
    <mesh name="link6_c"  file="link6.stl"/>
    <mesh name="link7_c"  file="link7.stl"/>

    <!-- visual meshes -->
    <mesh file="link0_0.obj"/>  <mesh file="link0_1.obj"/>  <mesh file="link0_2.obj"/>
    <mesh file="link0_3.obj"/>  <mesh file="link0_4.obj"/>  <mesh file="link0_5.obj"/>
    <mesh file="link0_7.obj"/>  <mesh file="link0_8.obj"/>  <mesh file="link0_9.obj"/>
    <mesh file="link0_10.obj"/> <mesh file="link0_11.obj"/>
    <mesh file="link1.obj"/>    <mesh file="link2.obj"/>
    <mesh file="link3_0.obj"/>  <mesh file="link3_1.obj"/>  <mesh file="link3_2.obj"/>  <mesh file="link3_3.obj"/>
    <mesh file="link4_0.obj"/>  <mesh file="link4_1.obj"/>  <mesh file="link4_2.obj"/>  <mesh file="link4_3.obj"/>
    <mesh file="link5_0.obj"/>  <mesh file="link5_1.obj"/>  <mesh file="link5_2.obj"/>
    <mesh file="link6_0.obj"/>  <mesh file="link6_1.obj"/>  <mesh file="link6_2.obj"/>  <mesh file="link6_3.obj"/>
    <mesh file="link6_4.obj"/>  <mesh file="link6_5.obj"/>  <mesh file="link6_6.obj"/>  <mesh file="link6_7.obj"/>
    <mesh file="link6_8.obj"/>  <mesh file="link6_9.obj"/>  <mesh file="link6_10.obj"/> <mesh file="link6_11.obj"/>
    <mesh file="link6_12.obj"/> <mesh file="link6_13.obj"/> <mesh file="link6_14.obj"/> <mesh file="link6_15.obj"/>
    <mesh file="link6_16.obj"/>
    <mesh file="link7_0.obj"/>  <mesh file="link7_1.obj"/>  <mesh file="link7_2.obj"/>  <mesh file="link7_3.obj"/>
    <mesh file="link7_4.obj"/>  <mesh file="link7_5.obj"/>  <mesh file="link7_6.obj"/>  <mesh file="link7_7.obj"/>
  </asset>

  <!-- ═══════════════════════════════════════════════
       WORLD
  ════════════════════════════════════════════════════ -->
  <worldbody>
    <light pos="0 0 2.5" dir="0 0 -1" directional="true"/>
    <light pos="-1 0 2" dir="0.5 0 -1"  directional="false" diffuse="0.4 0.4 0.4"/>
    <light pos=" 1 0 2" dir="-0.5 0 -1" directional="false" diffuse="0.4 0.4 0.4"/>
    <geom name="floor" size="0 0 0.05" type="plane" material="groundplane"/>

    <!-- ── Cuboid base platform (top surface at z=0.2) ── -->
    <geom name="base_platform" type="box"
          size="0.85 0.3 0.1" pos="0 0 0.1" material="base_mat"/>

    <!-- ── Centre pole ── -->
    <geom name="centre_pole" type="cylinder"
          fromto="0 0 0.2  0 0 0.9" size="0.04" material="pole_mat"/>
    <geom name="pole_cap" type="sphere"
          size="0.055" pos="0 0 0.92" material="pole_mat"/>

    <!-- ══════════════════════════════════════════════════════
         PANDA 1  –  left (x=-0.55), facing +Y
    ═══════════════════════════════════════════════════════════ -->
    <body name="p1_link0" childclass="panda" pos="-0.55 0 0.2" euler="0 0 1.5708">
      <inertial mass="0.629769" pos="-0.041018 -0.00014 0.049974"
        fullinertia="0.00315 0.00388 0.004285 8.2904e-7 0.00015 8.2299e-6"/>
      <geom mesh="link0_0"  material="off_white"  class="panda/visual"/>
      <geom mesh="link0_1"  material="dark_grey"  class="panda/visual"/>
      <geom mesh="link0_2"  material="off_white"  class="panda/visual"/>
      <geom mesh="link0_3"  material="dark_grey"  class="panda/visual"/>
      <geom mesh="link0_4"  material="off_white"  class="panda/visual"/>
      <geom mesh="link0_5"  material="dark_grey"  class="panda/visual"/>
      <geom mesh="link0_7"  material="white"      class="panda/visual"/>
      <geom mesh="link0_8"  material="white"      class="panda/visual"/>
      <geom mesh="link0_9"  material="dark_grey"  class="panda/visual"/>
      <geom mesh="link0_10" material="off_white"  class="panda/visual"/>
      <geom mesh="link0_11" material="white"      class="panda/visual"/>
      <geom mesh="link0_c"  class="panda/collision"/>
      <body name="p1_link1" pos="0 0 0.333">
        <inertial mass="4.970684" pos="0.003875 0.002081 -0.04762"
          fullinertia="0.70337 0.70661 0.0091170 -0.00013900 0.0067720 0.019169"/>
        <joint name="p1_joint1"/>
        <geom material="white" mesh="link1" class="panda/visual"/>
        <geom mesh="link1_c" class="panda/collision"/>
        <body name="p1_link2" quat="1 -1 0 0">
          <inertial mass="0.646926" pos="-0.003141 -0.02872 0.003495"
            fullinertia="0.0079620 2.8110e-2 2.5995e-2 -3.925e-3 1.0254e-2 7.04e-4"/>
          <joint name="p1_joint2" range="-1.7628 1.7628"/>
          <geom material="white" mesh="link2" class="panda/visual"/>
          <geom mesh="link2_c" class="panda/collision"/>
          <body name="p1_link3" pos="0 -0.316 0" quat="1 1 0 0">
            <joint name="p1_joint3"/>
            <inertial mass="3.228604" pos="2.7518e-2 3.9252e-2 -6.6502e-2"
              fullinertia="3.7242e-2 3.6155e-2 1.083e-2 -4.761e-3 -1.1396e-2 -1.2805e-2"/>
            <geom mesh="link3_0" material="white"     class="panda/visual"/>
            <geom mesh="link3_1" material="white"     class="panda/visual"/>
            <geom mesh="link3_2" material="white"     class="panda/visual"/>
            <geom mesh="link3_3" material="dark_grey" class="panda/visual"/>
            <geom mesh="link3_c" class="panda/collision"/>
            <body name="p1_link4" pos="0.0825 0 0" quat="1 1 0 0">
              <inertial mass="3.587895" pos="-5.317e-2 1.04419e-1 2.7454e-2"
                fullinertia="2.5853e-2 1.9552e-2 2.8323e-2 7.796e-3 -1.332e-3 8.641e-3"/>
              <joint name="p1_joint4" range="-3.0718 -0.0698"/>
              <geom mesh="link4_0" material="white"     class="panda/visual"/>
              <geom mesh="link4_1" material="white"     class="panda/visual"/>
              <geom mesh="link4_2" material="dark_grey" class="panda/visual"/>
              <geom mesh="link4_3" material="white"     class="panda/visual"/>
              <geom mesh="link4_c" class="panda/collision"/>
              <body name="p1_link5" pos="-0.0825 0.384 0" quat="1 -1 0 0">
                <inertial mass="1.225946" pos="-1.1953e-2 4.1065e-2 -3.8437e-2"
                  fullinertia="3.5549e-2 2.9474e-2 8.627e-3 -2.117e-3 -4.037e-3 2.29e-4"/>
                <joint name="p1_joint5"/>
                <geom mesh="link5_0" material="dark_grey" class="panda/visual"/>
                <geom mesh="link5_1" material="white"     class="panda/visual"/>
                <geom mesh="link5_2" material="white"     class="panda/visual"/>
                <geom mesh="link5_c0" class="panda/collision"/>
                <geom mesh="link5_c1" class="panda/collision"/>
                <geom mesh="link5_c2" class="panda/collision"/>
                <body name="p1_link6" quat="1 1 0 0">
                  <inertial mass="1.666555" pos="6.0149e-2 -1.4117e-2 -1.0517e-2"
                    fullinertia="1.964e-3 4.354e-3 5.433e-3 1.09e-4 -1.158e-3 3.41e-4"/>
                  <joint name="p1_joint6" range="-0.0175 3.7525"/>
                  <geom mesh="link6_0"  material="off_white"  class="panda/visual"/>
                  <geom mesh="link6_1"  material="white"      class="panda/visual"/>
                  <geom mesh="link6_2"  material="dark_grey"  class="panda/visual"/>
                  <geom mesh="link6_3"  material="white"      class="panda/visual"/>
                  <geom mesh="link6_4"  material="white"      class="panda/visual"/>
                  <geom mesh="link6_5"  material="white"      class="panda/visual"/>
                  <geom mesh="link6_6"  material="white"      class="panda/visual"/>
                  <geom mesh="link6_7"  material="light_blue" class="panda/visual"/>
                  <geom mesh="link6_8"  material="light_blue" class="panda/visual"/>
                  <geom mesh="link6_9"  material="dark_grey"  class="panda/visual"/>
                  <geom mesh="link6_10" material="dark_grey"  class="panda/visual"/>
                  <geom mesh="link6_11" material="white"      class="panda/visual"/>
                  <geom mesh="link6_12" material="green"      class="panda/visual"/>
                  <geom mesh="link6_13" material="white"      class="panda/visual"/>
                  <geom mesh="link6_14" material="dark_grey"  class="panda/visual"/>
                  <geom mesh="link6_15" material="dark_grey"  class="panda/visual"/>
                  <geom mesh="link6_16" material="white"      class="panda/visual"/>
                  <geom mesh="link6_c" class="panda/collision"/>
                  <body name="p1_link7" pos="0.088 0 0" quat="1 1 0 0">
                    <inertial mass="7.35522e-01" pos="1.0517e-2 -4.252e-3 6.1597e-2"
                      fullinertia="1.2516e-2 1.0027e-2 4.815e-3 -4.28e-4 -1.196e-3 -7.41e-4"/>
                    <joint name="p1_joint7"/>
                    <geom mesh="link7_0" material="white"     class="panda/visual"/>
                    <geom mesh="link7_1" material="dark_grey" class="panda/visual"/>
                    <geom mesh="link7_2" material="dark_grey" class="panda/visual"/>
                    <geom mesh="link7_3" material="dark_grey" class="panda/visual"/>
                    <geom mesh="link7_4" material="dark_grey" class="panda/visual"/>
                    <geom mesh="link7_5" material="dark_grey" class="panda/visual"/>
                    <geom mesh="link7_6" material="dark_grey" class="panda/visual"/>
                    <geom mesh="link7_7" material="white"     class="panda/visual"/>
                    <geom mesh="link7_c" class="panda/collision"/>
                    <body name="p1_attachment" pos="0 0 0.107" quat="0.3826834 0 0 0.9238795">
                      <site name="p1_attachment_site"/>
                    </body>
                  </body>
                </body>
              </body>
            </body>
          </body>
        </body>
      </body>
    </body>

    <!-- ══════════════════════════════════════════════════════
         PANDA 2  –  right (x=+0.55), facing +Y
    ═══════════════════════════════════════════════════════════ -->
    <body name="p2_link0" childclass="panda" pos="0.55 0 0.2" euler="0 0 1.5708">
      <inertial mass="0.629769" pos="-0.041018 -0.00014 0.049974"
        fullinertia="0.00315 0.00388 0.004285 8.2904e-7 0.00015 8.2299e-6"/>
      <geom mesh="link0_0"  material="off_white"  class="panda/visual"/>
      <geom mesh="link0_1"  material="dark_grey"  class="panda/visual"/>
      <geom mesh="link0_2"  material="off_white"  class="panda/visual"/>
      <geom mesh="link0_3"  material="dark_grey"  class="panda/visual"/>
      <geom mesh="link0_4"  material="off_white"  class="panda/visual"/>
      <geom mesh="link0_5"  material="dark_grey"  class="panda/visual"/>
      <geom mesh="link0_7"  material="white"      class="panda/visual"/>
      <geom mesh="link0_8"  material="white"      class="panda/visual"/>
      <geom mesh="link0_9"  material="dark_grey"  class="panda/visual"/>
      <geom mesh="link0_10" material="off_white"  class="panda/visual"/>
      <geom mesh="link0_11" material="white"      class="panda/visual"/>
      <geom mesh="link0_c"  class="panda/collision"/>
      <body name="p2_link1" pos="0 0 0.333">
        <inertial mass="4.970684" pos="0.003875 0.002081 -0.04762"
          fullinertia="0.70337 0.70661 0.0091170 -0.00013900 0.0067720 0.019169"/>
        <joint name="p2_joint1"/>
        <geom material="white" mesh="link1" class="panda/visual"/>
        <geom mesh="link1_c" class="panda/collision"/>
        <body name="p2_link2" quat="1 -1 0 0">
          <inertial mass="0.646926" pos="-0.003141 -0.02872 0.003495"
            fullinertia="0.0079620 2.8110e-2 2.5995e-2 -3.925e-3 1.0254e-2 7.04e-4"/>
          <joint name="p2_joint2" range="-1.7628 1.7628"/>
          <geom material="white" mesh="link2" class="panda/visual"/>
          <geom mesh="link2_c" class="panda/collision"/>
          <body name="p2_link3" pos="0 -0.316 0" quat="1 1 0 0">
            <joint name="p2_joint3"/>
            <inertial mass="3.228604" pos="2.7518e-2 3.9252e-2 -6.6502e-2"
              fullinertia="3.7242e-2 3.6155e-2 1.083e-2 -4.761e-3 -1.1396e-2 -1.2805e-2"/>
            <geom mesh="link3_0" material="white"     class="panda/visual"/>
            <geom mesh="link3_1" material="white"     class="panda/visual"/>
            <geom mesh="link3_2" material="white"     class="panda/visual"/>
            <geom mesh="link3_3" material="dark_grey" class="panda/visual"/>
            <geom mesh="link3_c" class="panda/collision"/>
            <body name="p2_link4" pos="0.0825 0 0" quat="1 1 0 0">
              <inertial mass="3.587895" pos="-5.317e-2 1.04419e-1 2.7454e-2"
                fullinertia="2.5853e-2 1.9552e-2 2.8323e-2 7.796e-3 -1.332e-3 8.641e-3"/>
              <joint name="p2_joint4" range="-3.0718 -0.0698"/>
              <geom mesh="link4_0" material="white"     class="panda/visual"/>
              <geom mesh="link4_1" material="white"     class="panda/visual"/>
              <geom mesh="link4_2" material="dark_grey" class="panda/visual"/>
              <geom mesh="link4_3" material="white"     class="panda/visual"/>
              <geom mesh="link4_c" class="panda/collision"/>
              <body name="p2_link5" pos="-0.0825 0.384 0" quat="1 -1 0 0">
                <inertial mass="1.225946" pos="-1.1953e-2 4.1065e-2 -3.8437e-2"
                  fullinertia="3.5549e-2 2.9474e-2 8.627e-3 -2.117e-3 -4.037e-3 2.29e-4"/>
                <joint name="p2_joint5"/>
                <geom mesh="link5_0" material="dark_grey" class="panda/visual"/>
                <geom mesh="link5_1" material="white"     class="panda/visual"/>
                <geom mesh="link5_2" material="white"     class="panda/visual"/>
                <geom mesh="link5_c0" class="panda/collision"/>
                <geom mesh="link5_c1" class="panda/collision"/>
                <geom mesh="link5_c2" class="panda/collision"/>
                <body name="p2_link6" quat="1 1 0 0">
                  <inertial mass="1.666555" pos="6.0149e-2 -1.4117e-2 -1.0517e-2"
                    fullinertia="1.964e-3 4.354e-3 5.433e-3 1.09e-4 -1.158e-3 3.41e-4"/>
                  <joint name="p2_joint6" range="-0.0175 3.7525"/>
                  <geom mesh="link6_0"  material="off_white"  class="panda/visual"/>
                  <geom mesh="link6_1"  material="white"      class="panda/visual"/>
                  <geom mesh="link6_2"  material="dark_grey"  class="panda/visual"/>
                  <geom mesh="link6_3"  material="white"      class="panda/visual"/>
                  <geom mesh="link6_4"  material="white"      class="panda/visual"/>
                  <geom mesh="link6_5"  material="white"      class="panda/visual"/>
                  <geom mesh="link6_6"  material="white"      class="panda/visual"/>
                  <geom mesh="link6_7"  material="light_blue" class="panda/visual"/>
                  <geom mesh="link6_8"  material="light_blue" class="panda/visual"/>
                  <geom mesh="link6_9"  material="dark_grey"  class="panda/visual"/>
                  <geom mesh="link6_10" material="dark_grey"  class="panda/visual"/>
                  <geom mesh="link6_11" material="white"      class="panda/visual"/>
                  <geom mesh="link6_12" material="green"      class="panda/visual"/>
                  <geom mesh="link6_13" material="white"      class="panda/visual"/>
                  <geom mesh="link6_14" material="dark_grey"  class="panda/visual"/>
                  <geom mesh="link6_15" material="dark_grey"  class="panda/visual"/>
                  <geom mesh="link6_16" material="white"      class="panda/visual"/>
                  <geom mesh="link6_c" class="panda/collision"/>
                  <body name="p2_link7" pos="0.088 0 0" quat="1 1 0 0">
                    <inertial mass="7.35522e-01" pos="1.0517e-2 -4.252e-3 6.1597e-2"
                      fullinertia="1.2516e-2 1.0027e-2 4.815e-3 -4.28e-4 -1.196e-3 -7.41e-4"/>
                    <joint name="p2_joint7"/>
                    <geom mesh="link7_0" material="white"     class="panda/visual"/>
                    <geom mesh="link7_1" material="dark_grey" class="panda/visual"/>
                    <geom mesh="link7_2" material="dark_grey" class="panda/visual"/>
                    <geom mesh="link7_3" material="dark_grey" class="panda/visual"/>
                    <geom mesh="link7_4" material="dark_grey" class="panda/visual"/>
                    <geom mesh="link7_5" material="dark_grey" class="panda/visual"/>
                    <geom mesh="link7_6" material="dark_grey" class="panda/visual"/>
                    <geom mesh="link7_7" material="white"     class="panda/visual"/>
                    <geom mesh="link7_c" class="panda/collision"/>
                    <body name="p2_attachment" pos="0 0 0.107" quat="0.3826834 0 0 0.9238795">
                      <site name="p2_attachment_site"/>
                    </body>
                  </body>
                </body>
              </body>
            </body>
          </body>
        </body>
      </body>
    </body>

  </worldbody>

  <!-- ═══════════════════════════════════════════════
       ACTUATORS  (7 per robot = 14 total, no gripper)
  ════════════════════════════════════════════════════ -->
  <actuator>
    <!-- Panda 1 -->
    <general class="panda" name="p1_actuator1" joint="p1_joint1" gainprm="4500" biasprm="0 -4500 -450"/>
    <general class="panda" name="p1_actuator2" joint="p1_joint2" gainprm="4500" biasprm="0 -4500 -450" ctrlrange="-1.7628 1.7628"/>
    <general class="panda" name="p1_actuator3" joint="p1_joint3" gainprm="3500" biasprm="0 -3500 -350"/>
    <general class="panda" name="p1_actuator4" joint="p1_joint4" gainprm="3500" biasprm="0 -3500 -350" ctrlrange="-3.0718 -0.0698"/>
    <general class="panda" name="p1_actuator5" joint="p1_joint5" gainprm="2000" biasprm="0 -2000 -200" forcerange="-12 12"/>
    <general class="panda" name="p1_actuator6" joint="p1_joint6" gainprm="2000" biasprm="0 -2000 -200" forcerange="-12 12" ctrlrange="-0.0175 3.7525"/>
    <general class="panda" name="p1_actuator7" joint="p1_joint7" gainprm="2000" biasprm="0 -2000 -200" forcerange="-12 12"/>

    <!-- Panda 2 -->
    <general class="panda" name="p2_actuator1" joint="p2_joint1" gainprm="4500" biasprm="0 -4500 -450"/>
    <general class="panda" name="p2_actuator2" joint="p2_joint2" gainprm="4500" biasprm="0 -4500 -450" ctrlrange="-1.7628 1.7628"/>
    <general class="panda" name="p2_actuator3" joint="p2_joint3" gainprm="3500" biasprm="0 -3500 -350"/>
    <general class="panda" name="p2_actuator4" joint="p2_joint4" gainprm="3500" biasprm="0 -3500 -350" ctrlrange="-3.0718 -0.0698"/>
    <general class="panda" name="p2_actuator5" joint="p2_joint5" gainprm="2000" biasprm="0 -2000 -200" forcerange="-12 12"/>
    <general class="panda" name="p2_actuator6" joint="p2_joint6" gainprm="2000" biasprm="0 -2000 -200" forcerange="-12 12" ctrlrange="-0.0175 3.7525"/>
    <general class="panda" name="p2_actuator7" joint="p2_joint7" gainprm="2000" biasprm="0 -2000 -200" forcerange="-12 12"/>
  </actuator>

  <!-- ═══════════════════════════════════════════════
       CONTACT EXCLUSIONS
  ════════════════════════════════════════════════════ -->
  <contact>
    <exclude body1="p1_link0" body2="p1_link1"/>
    <exclude body1="p2_link0" body2="p2_link1"/>
  </contact>

  <!-- ═══════════════════════════════════════════════
       KEYFRAME
       qpos: 7 per robot = 14 values (no finger joints)
       ctrl: 7 per robot = 14 values
  ════════════════════════════════════════════════════ -->
  <keyframe>
    <key name="home"
      qpos="0 0 0 -1.57079 0 1.57079 -0.7853
            0 0 0 -1.57079 0 1.57079 -0.7853"
      ctrl="0 0 0 -1.57079 0 1.57079 -0.7853
            0 0 0 -1.57079 0 1.57079 -0.7853"/>
  </keyframe>

</mujoco>
