<mujoco model="panda_with_tdcr_50seg_freeze12">
  <!--
    Single Franka Panda arm + 50-segment TDCR (freeze at seg 12)
    Scale factor: 0.1 (same as original two_pandas model)
    TDCR attached to link7 flange at pos="0 0 0.107"
    
    Actuator layout:
      actuator1-7  : Panda arm joints (position servos)
      A_1, A_2     : TDCR arm tendons (bend left/right)  
      A_3, A_4     : TDCR gripper tendons (open/close)
    
    Key sites:
      attachment_site : on link7, used for panda DLS IK
      tdcr_tip        : at gripper base, TDCR tip reference
  -->
  <compiler angle="radian" meshdir="assets" autolimits="true"/>
  <option integrator="implicitfast" impratio="10" gravity="0 0 -9.81"/>
  <size nconmax="5000" njmax="5000"/>
  <statistic center="0.3 0 0.5" extent="1.2"/>

  <visual>
    <headlight diffuse="0.6 0.6 0.6" ambient="0.3 0.3 0.3" specular="0 0 0"/>
    <rgba haze="0.15 0.25 0.35 1"/>
    <global azimuth="120" elevation="-20"/>
  </visual>

  <default>
    <default class="panda">
      <material specular="0.5" shininess="0.25"/>
      <joint armature="0.1" damping="1" axis="0 0 1" range="-2.8973 2.8973"/>
      <general dyntype="none" biastype="affine" ctrlrange="-2.8973 2.8973" forcerange="-87 87"/>
      <default class="panda/visual">
        <geom type="mesh" contype="0" conaffinity="0" group="2"/>
      </default>
      <default class="panda/collision">
        <geom type="mesh" group="3"/>
      </default>
      <site size="0.001" rgba="0.5 0.5 0.5 0.3" group="4"/>
    </default>
  </default>

  <asset>
    <texture type="skybox" builtin="gradient" rgb1="0.3 0.5 0.7" rgb2="0 0 0" width="512" height="3072"/>
    <texture type="2d" name="groundplane" builtin="checker" mark="edge"
      rgb1="0.2 0.3 0.4" rgb2="0.1 0.2 0.3" markrgb="0.8 0.8 0.8" width="300" height="300"/>
    <material name="groundplane" texture="groundplane" texuniform="true" texrepeat="5 5" reflectance="0.2"/>
    <material class="panda" name="white"      rgba="1 1 1 1"/>
    <material class="panda" name="off_white"  rgba="0.901961 0.921569 0.929412 1"/>
    <material class="panda" name="dark_grey"  rgba="0.25 0.25 0.25 1"/>
    <material class="panda" name="green"      rgba="0 1 0 1"/>
    <material class="panda" name="light_blue" rgba="0.039216 0.541176 0.780392 1"/>

    <!-- Panda collision meshes -->
    <mesh name="link0_c"  file="link0.stl"/>   <mesh name="link1_c" file="link1.stl"/>
    <mesh name="link2_c"  file="link2.stl"/>   <mesh name="link3_c" file="link3.stl"/>
    <mesh name="link4_c"  file="link4.stl"/>   <mesh name="link5_c0" file="link5_collision_0.obj"/>
    <mesh name="link5_c1" file="link5_collision_1.obj"/> <mesh name="link5_c2" file="link5_collision_2.obj"/>
    <mesh name="link6_c"  file="link6.stl"/>   <mesh name="link7_c" file="link7.stl"/>

    <!-- Panda visual meshes -->
    <mesh file="link0_0.obj"/> <mesh file="link0_1.obj"/> <mesh file="link0_2.obj"/> <mesh file="link0_3.obj"/>
    <mesh file="link0_4.obj"/> <mesh file="link0_5.obj"/> <mesh file="link0_7.obj"/> <mesh file="link0_8.obj"/>
    <mesh file="link0_9.obj"/> <mesh file="link0_10.obj"/> <mesh file="link0_11.obj"/>
    <mesh file="link1.obj"/>   <mesh file="link2.obj"/>
    <mesh file="link3_0.obj"/> <mesh file="link3_1.obj"/> <mesh file="link3_2.obj"/> <mesh file="link3_3.obj"/>
    <mesh file="link4_0.obj"/> <mesh file="link4_1.obj"/> <mesh file="link4_2.obj"/> <mesh file="link4_3.obj"/>
    <mesh file="link5_0.obj"/> <mesh file="link5_1.obj"/> <mesh file="link5_2.obj"/>
    <mesh file="link6_0.obj"/> <mesh file="link6_1.obj"/> <mesh file="link6_2.obj"/> <mesh file="link6_3.obj"/>
    <mesh file="link6_4.obj"/> <mesh file="link6_5.obj"/> <mesh file="link6_6.obj"/> <mesh file="link6_7.obj"/>
    <mesh file="link6_8.obj"/> <mesh file="link6_9.obj"/> <mesh file="link6_10.obj"/> <mesh file="link6_11.obj"/>
    <mesh file="link6_12.obj"/> <mesh file="link6_13.obj"/> <mesh file="link6_14.obj"/> <mesh file="link6_15.obj"/>
    <mesh file="link6_16.obj"/>
    <mesh file="link7_0.obj"/> <mesh file="link7_1.obj"/> <mesh file="link7_2.obj"/> <mesh file="link7_3.obj"/>
    <mesh file="link7_4.obj"/> <mesh file="link7_5.obj"/> <mesh file="link7_6.obj"/> <mesh file="link7_7.obj"/>

    <!-- TDCR meshes (0.1x scale, freeze at seg 12) -->
    <mesh name="platform_mesh" file="3D/p_platform.STL" scale="0.0001 0.0001 0.0001"/>
    <mesh name="base_mesh"     file="3D/P_0Base.STL"    scale="0.0001 0.0001 0.0001"/>
    <mesh name="segment_1_mesh" file="3D/P_1_3.STL" scale="0.00010000 0.00010000 0.00010000"/>
    <mesh name="segment_2_mesh" file="3D/P_1_3.STL" scale="0.00009127 0.00009127 0.00009127"/>
    <mesh name="segment_3_mesh" file="3D/P_1_3.STL" scale="0.00008329 0.00008329 0.00008329"/>
    <mesh name="segment_4_mesh" file="3D/P_1_3.STL" scale="0.00007602 0.00007602 0.00007602"/>
    <mesh name="segment_5_mesh" file="3D/P_1_3.STL" scale="0.00006938 0.00006938 0.00006938"/>
    <mesh name="segment_6_mesh" file="3D/P_1_3.STL" scale="0.00006332 0.00006332 0.00006332"/>
    <mesh name="segment_7_mesh" file="3D/P_1_3.STL" scale="0.00005779 0.00005779 0.00005779"/>
    <mesh name="segment_8_mesh" file="3D/P_1_3.STL" scale="0.00005274 0.00005274 0.00005274"/>
    <mesh name="segment_9_mesh" file="3D/P_1_3.STL" scale="0.00004814 0.00004814 0.00004814"/>
    <mesh name="segment_10_mesh" file="3D/P_1_3.STL" scale="0.00004393 0.00004393 0.00004393"/>
    <mesh name="segment_11_mesh" file="3D/P_1_3.STL" scale="0.00004009 0.00004009 0.00004009"/>
    <mesh name="segment_12_mesh" file="3D/P_1_3.STL" scale="0.00003659 0.00003659 0.00003659"/>
    <mesh name="segment_13_mesh" file="3D/P_1_3.STL" scale="0.00003659 0.00003659 0.00003659"/>
    <mesh name="segment_14_mesh" file="3D/P_1_3.STL" scale="0.00003659 0.00003659 0.00003659"/>
    <mesh name="segment_15_mesh" file="3D/P_1_3.STL" scale="0.00003659 0.00003659 0.00003659"/>
    <mesh name="segment_16_mesh" file="3D/P_1_3.STL" scale="0.00003659 0.00003659 0.00003659"/>
    <mesh name="segment_17_mesh" file="3D/P_1_3.STL" scale="0.00003659 0.00003659 0.00003659"/>
    <mesh name="segment_18_mesh" file="3D/P_1_3.STL" scale="0.00003659 0.00003659 0.00003659"/>
    <mesh name="segment_19_mesh" file="3D/P_1_3.STL" scale="0.00003659 0.00003659 0.00003659"/>
    <mesh name="segment_20_mesh" file="3D/P_1_3.STL" scale="0.00003659 0.00003659 0.00003659"/>
    <mesh name="segment_21_mesh" file="3D/P_1_3.STL" scale="0.00003659 0.00003659 0.00003659"/>
    <mesh name="segment_22_mesh" file="3D/P_1_3.STL" scale="0.00003659 0.00003659 0.00003659"/>
    <mesh name="segment_23_mesh" file="3D/P_1_3.STL" scale="0.00003659 0.00003659 0.00003659"/>
    <mesh name="segment_24_mesh" file="3D/P_1_3.STL" scale="0.00003659 0.00003659 0.00003659"/>
    <mesh name="segment_25_mesh" file="3D/P_1_3.STL" scale="0.00003659 0.00003659 0.00003659"/>
    <mesh name="segment_26_mesh" file="3D/P_1_3.STL" scale="0.00003659 0.00003659 0.00003659"/>
    <mesh name="segment_27_mesh" file="3D/P_1_3.STL" scale="0.00003659 0.00003659 0.00003659"/>
    <mesh name="segment_28_mesh" file="3D/P_1_3.STL" scale="0.00003659 0.00003659 0.00003659"/>
    <mesh name="segment_29_mesh" file="3D/P_1_3.STL" scale="0.00003659 0.00003659 0.00003659"/>
    <mesh name="segment_30_mesh" file="3D/P_1_3.STL" scale="0.00003659 0.00003659 0.00003659"/>
    <mesh name="segment_31_mesh" file="3D/P_1_3.STL" scale="0.00003659 0.00003659 0.00003659"/>
    <mesh name="segment_32_mesh" file="3D/P_1_3.STL" scale="0.00003659 0.00003659 0.00003659"/>
    <mesh name="segment_33_mesh" file="3D/P_1_3.STL" scale="0.00003659 0.00003659 0.00003659"/>
    <mesh name="segment_34_mesh" file="3D/P_1_3.STL" scale="0.00003659 0.00003659 0.00003659"/>
    <mesh name="segment_35_mesh" file="3D/P_1_3.STL" scale="0.00003659 0.00003659 0.00003659"/>
    <mesh name="segment_36_mesh" file="3D/P_1_3.STL" scale="0.00003659 0.00003659 0.00003659"/>
    <mesh name="segment_37_mesh" file="3D/P_1_3.STL" scale="0.00003659 0.00003659 0.00003659"/>
    <mesh name="segment_38_mesh" file="3D/P_1_3.STL" scale="0.00003659 0.00003659 0.00003659"/>
    <mesh name="segment_39_mesh" file="3D/P_1_3.STL" scale="0.00003659 0.00003659 0.00003659"/>
    <mesh name="segment_40_mesh" file="3D/P_1_3.STL" scale="0.00003659 0.00003659 0.00003659"/>
    <mesh name="segment_41_mesh" file="3D/P_1_3.STL" scale="0.00003659 0.00003659 0.00003659"/>
    <mesh name="segment_42_mesh" file="3D/P_1_3.STL" scale="0.00003659 0.00003659 0.00003659"/>
    <mesh name="segment_43_mesh" file="3D/P_1_3.STL" scale="0.00003659 0.00003659 0.00003659"/>
    <mesh name="segment_44_mesh" file="3D/P_1_3.STL" scale="0.00003659 0.00003659 0.00003659"/>
    <mesh name="segment_45_mesh" file="3D/P_1_3.STL" scale="0.00003659 0.00003659 0.00003659"/>
    <mesh name="segment_46_mesh" file="3D/P_1_3.STL" scale="0.00003659 0.00003659 0.00003659"/>
    <mesh name="segment_47_mesh" file="3D/P_1_3.STL" scale="0.00003659 0.00003659 0.00003659"/>
    <mesh name="segment_48_mesh" file="3D/P_1_3.STL" scale="0.00003659 0.00003659 0.00003659"/>
    <mesh name="segment_49_mesh" file="3D/P_1_3.STL" scale="0.00003659 0.00003659 0.00003659"/>
    <mesh name="segment_50_mesh" file="3D/P_1_3.STL" scale="0.00003659 0.00003659 0.00003659"/>
    <mesh name="gripper_base" file="3D_Gripper/gripper_base.STL" scale="0.1 0.1 0.1"/>
    <mesh name="gripper"      file="3D_Gripper/gripper.STL"      scale="0.1 0.1 0.1"/>
  </asset>

  <worldbody>
    <light pos="0 0 2.5" dir="0 0 -1" directional="true"/>
    <light pos="-1 0 2" dir="0.5 0 -1" directional="false" diffuse="0.4 0.4 0.4"/>
    <light pos=" 1 0 2" dir="-0.5 0 -1" directional="false" diffuse="0.4 0.4 0.4"/>
    <geom name="floor" size="0 0 0.05" type="plane" material="groundplane"/>

    <!-- ═══ PANDA ARM (single robot, base at origin) ═══ -->
    <body name="link0" childclass="panda" pos="0 0 0">
      <inertial mass="0.629769" pos="-0.041018 -0.00014 0.049974"
        fullinertia="0.00315 0.00388 0.004285 8.2904e-7 0.00015 8.2299e-6"/>
      <geom mesh="link0_0"  material="off_white"  class="panda/visual"/>
      <geom mesh="link0_1"  material="dark_grey"  class="panda/visual"/>
      <geom mesh="link0_2"  material="off_white"  class="panda/visual"/>
      <geom mesh="link0_3"  material="dark_grey"  class="panda/visual"/>
      <geom mesh="link0_4"  material="off_white"  class="panda/visual"/>
      <geom mesh="link0_5"  material="dark_grey"  class="panda/visual"/>
      <geom mesh="link0_7"  material="white"      class="panda/visual"/>
      <geom mesh="link0_8"  material="white"      class="panda/visual"/>
      <geom mesh="link0_9"  material="dark_grey"  class="panda/visual"/>
      <geom mesh="link0_10" material="off_white"  class="panda/visual"/>
      <geom mesh="link0_11" material="white"      class="panda/visual"/>
      <geom mesh="link0_c"  class="panda/collision"/>
      <body name="link1" pos="0 0 0.333">
        <inertial mass="4.970684" pos="0.003875 0.002081 -0.04762"
          fullinertia="0.70337 0.70661 0.0091170 -0.00013900 0.0067720 0.019169"/>
        <joint name="joint1"/>
        <geom material="white" mesh="link1" class="panda/visual"/>
        <geom mesh="link1_c" class="panda/collision"/>
        <body name="link2" quat="1 -1 0 0">
          <inertial mass="0.646926" pos="-0.003141 -0.02872 0.003495"
            fullinertia="0.0079620 2.8110e-2 2.5995e-2 -3.925e-3 1.0254e-2 7.04e-4"/>
          <joint name="joint2" range="-1.7628 1.7628"/>
          <geom material="white" mesh="link2" class="panda/visual"/>
          <geom mesh="link2_c" class="panda/collision"/>
          <body name="link3" pos="0 -0.316 0" quat="1 1 0 0">
            <joint name="joint3"/>
            <inertial mass="3.228604" pos="2.7518e-2 3.9252e-2 -6.6502e-2"
              fullinertia="3.7242e-2 3.6155e-2 1.083e-2 -4.761e-3 -1.1396e-2 -1.2805e-2"/>
            <geom mesh="link3_0" material="white"     class="panda/visual"/>
            <geom mesh="link3_1" material="white"     class="panda/visual"/>
            <geom mesh="link3_2" material="white"     class="panda/visual"/>
            <geom mesh="link3_3" material="dark_grey" class="panda/visual"/>
            <geom mesh="link3_c" class="panda/collision"/>
            <body name="link4" pos="0.0825 0 0" quat="1 1 0 0">
              <inertial mass="3.587895" pos="-5.317e-2 1.04419e-1 2.7454e-2"
                fullinertia="2.5853e-2 1.9552e-2 2.8323e-2 7.796e-3 -1.332e-3 8.641e-3"/>
              <joint name="joint4" range="-3.0718 -0.0698"/>
              <geom mesh="link4_0" material="white"     class="panda/visual"/>
              <geom mesh="link4_1" material="white"     class="panda/visual"/>
              <geom mesh="link4_2" material="dark_grey" class="panda/visual"/>
              <geom mesh="link4_3" material="white"     class="panda/visual"/>
              <geom mesh="link4_c" class="panda/collision"/>
              <body name="link5" pos="-0.0825 0.384 0" quat="1 -1 0 0">
                <inertial mass="1.225946" pos="-1.1953e-2 4.1065e-2 -3.8437e-2"
                  fullinertia="3.5549e-2 2.9474e-2 8.627e-3 -2.117e-3 -4.037e-3 2.29e-4"/>
                <joint name="joint5"/>
                <geom mesh="link5_0" material="dark_grey" class="panda/visual"/>
                <geom mesh="link5_1" material="white"     class="panda/visual"/>
                <geom mesh="link5_2" material="white"     class="panda/visual"/>
                <geom mesh="link5_c0" class="panda/collision"/>
                <geom mesh="link5_c1" class="panda/collision"/>
                <geom mesh="link5_c2" class="panda/collision"/>
                <body name="link6" quat="1 1 0 0">
                  <inertial mass="1.666555" pos="6.0149e-2 -1.4117e-2 -1.0517e-2"
                    fullinertia="1.964e-3 4.354e-3 5.433e-3 1.09e-4 -1.158e-3 3.41e-4"/>
                  <joint name="joint6" range="-0.0175 3.7525"/>
                  <geom mesh="link6_0"  material="off_white"  class="panda/visual"/>
                  <geom mesh="link6_1"  material="white"      class="panda/visual"/>
                  <geom mesh="link6_2"  material="dark_grey"  class="panda/visual"/>
                  <geom mesh="link6_3"  material="white"      class="panda/visual"/>
                  <geom mesh="link6_4"  material="white"      class="panda/visual"/>
                  <geom mesh="link6_5"  material="white"      class="panda/visual"/>
                  <geom mesh="link6_6"  material="white"      class="panda/visual"/>
                  <geom mesh="link6_7"  material="light_blue" class="panda/visual"/>
                  <geom mesh="link6_8"  material="light_blue" class="panda/visual"/>
                  <geom mesh="link6_9"  material="dark_grey"  class="panda/visual"/>
                  <geom mesh="link6_10" material="dark_grey"  class="panda/visual"/>
                  <geom mesh="link6_11" material="white"      class="panda/visual"/>
                  <geom mesh="link6_12" material="green"      class="panda/visual"/>
                  <geom mesh="link6_13" material="white"      class="panda/visual"/>
                  <geom mesh="link6_14" material="dark_grey"  class="panda/visual"/>
                  <geom mesh="link6_15" material="dark_grey"  class="panda/visual"/>
                  <geom mesh="link6_16" material="white"      class="panda/visual"/>
                  <geom mesh="link6_c"  class="panda/collision"/>
                  <body name="link7" pos="0.088 0 0" quat="1 1 0 0">
                    <inertial mass="7.35522e-01" pos="1.0517e-2 -4.252e-3 6.1597e-2"
                      fullinertia="1.2516e-2 1.0027e-2 4.815e-3 -4.28e-4 -1.196e-3 -7.41e-4"/>
                    <joint name="joint7"/>
                    <geom mesh="link7_0" material="white"     class="panda/visual"/>
                    <geom mesh="link7_1" material="dark_grey" class="panda/visual"/>
                    <geom mesh="link7_2" material="dark_grey" class="panda/visual"/>
                    <geom mesh="link7_3" material="dark_grey" class="panda/visual"/>
                    <geom mesh="link7_4" material="dark_grey" class="panda/visual"/>
                    <geom mesh="link7_5" material="dark_grey" class="panda/visual"/>
                    <geom mesh="link7_6" material="dark_grey" class="panda/visual"/>
                    <geom mesh="link7_7" material="white"     class="panda/visual"/>
                    <geom mesh="link7_c" class="panda/collision"/>

                    <!-- ═══ TDCR ATTACHMENT (flange at 107mm from link7 origin) ═══ -->
                    <body name="attachment" pos="0 0 0.107" quat="0.3826834 0 0 0.9238795">
                      <!-- attachment_site: EE reference for panda DLS IK -->
                      <site name="attachment_site" size="0.01" rgba="0 1 0 0.5"/>
                      <body name="tdcr_platform" pos="0 0 0" euler="0 0 0">
                        <geom type="mesh" mesh="platform_mesh" rgba="0.6 0.6 0.6 1"/>
                        <body name="tdcr_base" pos="0 0.007 0.014" euler="-0.524 0 1.57">
                          <geom type="mesh" mesh="base_mesh" rgba="0.3 0.3 0.8 1"/>
                          <site name="b_1" pos="-0.00725 0 0.002" size="0.002 0.002 0.002"/>
                          <site name="b_2" pos=" 0.00725 0 0.002" size="0.002 0.002 0.002"/>
                        </body>
                        <body name="segment_1" pos="0 0.0126 0.02362" euler="-0.524 3.14159 1.5708">
                          <geom type="mesh" mesh="segment_1_mesh" rgba="0.9 0.3 0.3 1"/>
                          <joint name="tdcr_Joint1" pos="0 0 0.00860000" axis="0 -1 0" limited="true" range="-0.523 0.523" stiffness="0.08164700" damping="0.08329500"/>
                          <inertial pos="0 0 0" quat="1 0 0 0" mass="0.00760200" diaginertia="3.640000e-04 3.640000e-04 4.571100e-04"/>
                          <site name="s1_1" pos=" 0.00690 0 0.00525" size="0.002 0.002 0.002"/>
                          <site name="s1_2" pos="-0.00690 0 0.00525" size="0.002 0.002 0.002"/>
                          <site name="s1_3" pos=" 0.00650 0 0.00050" size="0.002 0.002 0.002"/>
                          <site name="s1_4" pos="-0.00650 0 0.00050" size="0.002 0.002 0.002"/>
                          <body name="segment_2" pos="0 0 -0.007820">
                            <geom type="mesh" mesh="segment_2_mesh" rgba="0.9 0.3 0.3 1"/>
                            <joint name="tdcr_Joint2" pos="0 0 0.00782000" axis="0 -1 0" limited="true" range="-0.523 0.523" stiffness="0.03469200" damping="0.00693847"/>
                            <inertial pos="0 0 0" quat="1 0 0 0" mass="0.00577752" diaginertia="3.032120e-04 3.032120e-04 3.807730e-04"/>
                            <site name="s2_1" pos=" 0.00635 0 0.00500" size="0.002 0.002 0.002"/>
                            <site name="s2_2" pos="-0.00635 0 0.00500" size="0.002 0.002 0.002"/>
                            <site name="s2_3" pos=" 0.00600 0 0.00050" size="0.002 0.002 0.002"/>
                            <site name="s2_4" pos="-0.00600 0 0.00050" size="0.002 0.002 0.002"/>
                            <body name="segment_3" pos="0 0 -0.007135">
                              <geom type="mesh" mesh="segment_3_mesh" rgba="0.9 0.3 0.3 1"/>
                              <joint name="tdcr_Joint3" pos="0 0 0.00713800" axis="0 -1 0" limited="true" range="-0.523 0.523" stiffness="0.02889840" damping="0.00577975"/>
                              <inertial pos="0 0 0" quat="1 0 0 0" mass="0.00439092" diaginertia="2.525760e-04 2.525760e-04 3.171840e-04"/>
                              <site name="s3_1" pos=" 0.00580 0 0.00450" size="0.002 0.002 0.002"/>
                              <site name="s3_2" pos="-0.00580 0 0.00450" size="0.002 0.002 0.002"/>
                              <site name="s3_3" pos=" 0.00550 0 0.00050" size="0.002 0.002 0.002"/>
                              <site name="s3_4" pos="-0.00550 0 0.00050" size="0.002 0.002 0.002"/>
                              <body name="segment_4" pos="0 0 -0.006511">
                                <geom type="mesh" mesh="segment_4_mesh" rgba="0.9 0.3 0.3 1"/>
                                <joint name="tdcr_Joint4" pos="0 0 0.00653763" axis="0 -1 0" limited="true" range="-0.523 0.523" stiffness="0.02407240" damping="0.00481453"/>
                                <inertial pos="0 0 0" quat="1 0 0 0" mass="0.00333710" diaginertia="2.103950e-04 2.103950e-04 2.642140e-04"/>
                                <site name="s4_1" pos=" 0.00525 0 0.00400" size="0.002 0.002 0.002"/>
                                <site name="s4_2" pos="-0.00525 0 0.00400" size="0.002 0.002 0.002"/>
                                <site name="s4_3" pos=" 0.00500 0 0.00050" size="0.002 0.002 0.002"/>
                                <site name="s4_4" pos="-0.00500 0 0.00050" size="0.002 0.002 0.002"/>
                                <body name="segment_5" pos="0 0 -0.005940">
                                  <geom type="mesh" mesh="segment_5_mesh" rgba="0.9 0.3 0.3 1"/>
                                  <joint name="tdcr_Joint5" pos="0 0 0.00596668" axis="0 -1 0" limited="true" range="-0.523 0.523" stiffness="0.02005230" damping="0.00401050"/>
                                  <inertial pos="0 0 0" quat="1 0 0 0" mass="0.00253619" diaginertia="1.752590e-04 1.752590e-04 2.200900e-04"/>
                                  <site name="s5_1" pos=" 0.00475 0 0.00375" size="0.002 0.002 0.002"/>
                                  <site name="s5_2" pos="-0.00475 0 0.00375" size="0.002 0.002 0.002"/>
                                  <site name="s5_3" pos=" 0.00450 0 0.00050" size="0.002 0.002 0.002"/>
                                  <site name="s5_4" pos="-0.00450 0 0.00050" size="0.002 0.002 0.002"/>
                                  <body name="segment_6" pos="0 0 -0.005420">
                                    <geom type="mesh" mesh="segment_6_mesh" rgba="0.9 0.3 0.3 1"/>
                                    <joint name="tdcr_Joint6" pos="0 0 0.00544552" axis="0 -1 0" limited="true" range="-0.523 0.523" stiffness="0.01670350" damping="0.00334075"/>
                                    <inertial pos="0 0 0" quat="1 0 0 0" mass="0.00192751" diaginertia="1.459910e-04 1.459910e-04 1.833350e-04"/>
                                    <site name="s6_1" pos=" 0.00425 0 0.00350" size="0.002 0.002 0.002"/>
                                    <site name="s6_2" pos="-0.00425 0 0.00350" size="0.002 0.002 0.002"/>
                                    <site name="s6_3" pos=" 0.00400 0 0.00050" size="0.002 0.002 0.002"/>
                                    <site name="s6_4" pos="-0.00400 0 0.00050" size="0.002 0.002 0.002"/>
                                    <body name="segment_7" pos="0 0 -0.004950">
                                      <geom type="mesh" mesh="segment_7_mesh" rgba="0.9 0.3 0.3 1"/>
                                      <joint name="tdcr_Joint7" pos="0 0 0.00496994" axis="0 -1 0" limited="true" range="-0.523 0.523" stiffness="0.01391410" damping="0.00278284"/>
                                      <inertial pos="0 0 0" quat="1 0 0 0" mass="0.00146490" diaginertia="1.216110e-04 1.216110e-04 1.527180e-04"/>
                                      <site name="s7_1" pos=" 0.00390 0 0.00310" size="0.002 0.002 0.002"/>
                                      <site name="s7_2" pos="-0.00390 0 0.00310" size="0.002 0.002 0.002"/>
                                      <site name="s7_3" pos=" 0.00365 0 0.00033" size="0.002 0.002 0.002"/>
                                      <site name="s7_4" pos="-0.00365 0 0.00033" size="0.002 0.002 0.002"/>
                                      <body name="segment_8" pos="0 0 -0.004515">
                                        <geom type="mesh" mesh="segment_8_mesh" rgba="0.9 0.3 0.3 1"/>
                                        <joint name="tdcr_Joint8" pos="0 0 0.00453581" axis="0 -1 0" limited="true" range="-0.523 0.523" stiffness="0.01159040" damping="0.00231811"/>
                                        <inertial pos="0 0 0" quat="1 0 0 0" mass="0.00111333" diaginertia="1.013020e-04 1.013020e-04 1.272140e-04"/>
                                        <site name="s8_1" pos=" 0.00350 0 0.00295" size="0.002 0.002 0.002"/>
                                        <site name="s8_2" pos="-0.00350 0 0.00295" size="0.002 0.002 0.002"/>
                                        <site name="s8_3" pos=" 0.00327 0 0.00026" size="0.002 0.002 0.002"/>
                                        <site name="s8_4" pos="-0.00327 0 0.00026" size="0.002 0.002 0.002"/>
                                        <body name="segment_9" pos="0 0 -0.004120">
                                          <geom type="mesh" mesh="segment_9_mesh" rgba="0.9 0.3 0.3 1"/>
                                          <joint name="tdcr_Joint9" pos="0 0 0.00413961" axis="0 -1 0" limited="true" range="-0.523 0.523" stiffness="0.00965481" damping="0.00193099"/>
                                          <inertial pos="0 0 0" quat="1 0 0 0" mass="0.00084613" diaginertia="8.438430e-05 8.438430e-05 1.059690e-04"/>
                                          <site name="s9_1" pos=" 0.00322 0 0.00260" size="0.002 0.002 0.002"/>
                                          <site name="s9_2" pos="-0.00322 0 0.00260" size="0.002 0.002 0.002"/>
                                          <site name="s9_3" pos=" 0.00300 0 0.00019" size="0.002 0.002 0.002"/>
                                          <site name="s9_4" pos="-0.00300 0 0.00019" size="0.002 0.002 0.002"/>
                                          <body name="segment_10" pos="0 0 -0.003760">
                                            <geom type="mesh" mesh="segment_10_mesh" rgba="0.9 0.3 0.3 1"/>
                                            <joint name="tdcr_Joint10" pos="0 0 0.00377807" axis="0 -1 0" limited="true" range="-0.523 0.523" stiffness="0.00804246" damping="0.00160851"/>
                                            <inertial pos="0 0 0" quat="1 0 0 0" mass="0.00064306" diaginertia="7.029210e-05 7.029210e-05 8.827260e-05"/>
                                            <site name="s10_1" pos=" 0.00294 0 0.00235" size="0.002 0.002 0.002"/>
                                            <site name="s10_2" pos="-0.00294 0 0.00235" size="0.002 0.002 0.002"/>
                                            <site name="s10_3" pos=" 0.00276 0 0.00021" size="0.002 0.002 0.002"/>
                                            <site name="s10_4" pos="-0.00276 0 0.00021" size="0.002 0.002 0.002"/>
                                            <body name="segment_11" pos="0 0 -0.003430">
                                              <geom type="mesh" mesh="segment_11_mesh" rgba="0.9 0.3 0.3 1"/>
                                              <joint name="tdcr_Joint11" pos="0 0 0.00344808" axis="0 -1 0" limited="true" range="-0.523 0.523" stiffness="0.00669937" damping="0.00133989"/>
                                              <inertial pos="0 0 0" quat="1 0 0 0" mass="0.00048872" diaginertia="5.855330e-05 5.855330e-05 7.353100e-05"/>
                                              <site name="s11_1" pos=" 0.00280 0 0.00215" size="0.002 0.002 0.002"/>
                                              <site name="s11_2" pos="-0.00280 0 0.00215" size="0.002 0.002 0.002"/>
                                              <site name="s11_3" pos=" 0.00249 0 0.00020" size="0.002 0.002 0.002"/>
                                              <site name="s11_4" pos="-0.00249 0 0.00020" size="0.002 0.002 0.002"/>
                                              <body name="segment_12" pos="0 0 -0.003130">
                                                <geom type="mesh" mesh="segment_12_mesh" rgba="0.9 0.3 0.3 1"/>
                                                <joint name="tdcr_Joint12" pos="0 0 0.00314691" axis="0 -1 0" limited="true" range="-0.523 0.523" stiffness="0.00558057" damping="0.00111613"/>
                                                <inertial pos="0 0 0" quat="1 0 0 0" mass="0.00037143" diaginertia="4.877490e-05 4.877490e-05 6.125140e-05"/>
                                                <site name="s12_1" pos=" 0.00240 0 0.00197" size="0.002 0.002 0.002"/>
                                                <site name="s12_2" pos="-0.00240 0 0.00197" size="0.002 0.002 0.002"/>
                                                <site name="s12_3" pos=" 0.00225 0 0.00020" size="0.002 0.002 0.002"/>
                                                <site name="s12_4" pos="-0.00225 0 0.00020" size="0.002 0.002 0.002"/>
                                                <body name="segment_13" pos="0 0 -0.003130">
                                                  <geom type="mesh" mesh="segment_13_mesh" rgba="0.9 0.3 0.3 1"/>
                                                  <joint name="tdcr_Joint13" pos="0 0 0.00314691" axis="0 -1 0" limited="true" range="-0.523 0.523" stiffness="0.00558057" damping="0.00111613"/>
                                                  <inertial pos="0 0 0" quat="1 0 0 0" mass="0.00037143" diaginertia="4.877490e-05 4.877490e-05 6.125140e-05"/>
                                                  <site name="s13_1" pos=" 0.00240 0 0.00197" size="0.002 0.002 0.002"/>
                                                  <site name="s13_2" pos="-0.00240 0 0.00197" size="0.002 0.002 0.002"/>
                                                  <site name="s13_3" pos=" 0.00225 0 0.00020" size="0.002 0.002 0.002"/>
                                                  <site name="s13_4" pos="-0.00225 0 0.00020" size="0.002 0.002 0.002"/>
                                                  <body name="segment_14" pos="0 0 -0.003130">
                                                    <geom type="mesh" mesh="segment_14_mesh" rgba="0.9 0.3 0.3 1"/>
                                                    <joint name="tdcr_Joint14" pos="0 0 0.00314691" axis="0 -1 0" limited="true" range="-0.523 0.523" stiffness="0.00558057" damping="0.00111613"/>
                                                    <inertial pos="0 0 0" quat="1 0 0 0" mass="0.00037143" diaginertia="4.877490e-05 4.877490e-05 6.125140e-05"/>
                                                    <site name="s14_1" pos=" 0.00240 0 0.00197" size="0.002 0.002 0.002"/>
                                                    <site name="s14_2" pos="-0.00240 0 0.00197" size="0.002 0.002 0.002"/>
                                                    <site name="s14_3" pos=" 0.00225 0 0.00020" size="0.002 0.002 0.002"/>
                                                    <site name="s14_4" pos="-0.00225 0 0.00020" size="0.002 0.002 0.002"/>
                                                    <body name="segment_15" pos="0 0 -0.003130">
                                                      <geom type="mesh" mesh="segment_15_mesh" rgba="0.9 0.3 0.3 1"/>
                                                      <joint name="tdcr_Joint15" pos="0 0 0.00314691" axis="0 -1 0" limited="true" range="-0.523 0.523" stiffness="0.00558057" damping="0.00111613"/>
                                                      <inertial pos="0 0 0" quat="1 0 0 0" mass="0.00037143" diaginertia="4.877490e-05 4.877490e-05 6.125140e-05"/>
                                                      <site name="s15_1" pos=" 0.00240 0 0.00197" size="0.002 0.002 0.002"/>
                                                      <site name="s15_2" pos="-0.00240 0 0.00197" size="0.002 0.002 0.002"/>
                                                      <site name="s15_3" pos=" 0.00225 0 0.00020" size="0.002 0.002 0.002"/>
                                                      <site name="s15_4" pos="-0.00225 0 0.00020" size="0.002 0.002 0.002"/>
                                                      <body name="segment_16" pos="0 0 -0.003130">
                                                        <geom type="mesh" mesh="segment_16_mesh" rgba="0.9 0.3 0.3 1"/>
                                                        <joint name="tdcr_Joint16" pos="0 0 0.00314691" axis="0 -1 0" limited="true" range="-0.523 0.523" stiffness="0.00558057" damping="0.00111613"/>
                                                        <inertial pos="0 0 0" quat="1 0 0 0" mass="0.00037143" diaginertia="4.877490e-05 4.877490e-05 6.125140e-05"/>
                                                        <site name="s16_1" pos=" 0.00240 0 0.00197" size="0.002 0.002 0.002"/>
                                                        <site name="s16_2" pos="-0.00240 0 0.00197" size="0.002 0.002 0.002"/>
                                                        <site name="s16_3" pos=" 0.00225 0 0.00020" size="0.002 0.002 0.002"/>
                                                        <site name="s16_4" pos="-0.00225 0 0.00020" size="0.002 0.002 0.002"/>
                                                        <body name="segment_17" pos="0 0 -0.003130">
                                                          <geom type="mesh" mesh="segment_17_mesh" rgba="0.9 0.3 0.3 1"/>
                                                          <joint name="tdcr_Joint17" pos="0 0 0.00314691" axis="0 -1 0" limited="true" range="-0.523 0.523" stiffness="0.00558057" damping="0.00111613"/>
                                                          <inertial pos="0 0 0" quat="1 0 0 0" mass="0.00037143" diaginertia="4.877490e-05 4.877490e-05 6.125140e-05"/>
                                                          <site name="s17_1" pos=" 0.00240 0 0.00197" size="0.002 0.002 0.002"/>
                                                          <site name="s17_2" pos="-0.00240 0 0.00197" size="0.002 0.002 0.002"/>
                                                          <site name="s17_3" pos=" 0.00225 0 0.00020" size="0.002 0.002 0.002"/>
                                                          <site name="s17_4" pos="-0.00225 0 0.00020" size="0.002 0.002 0.002"/>
                                                          <body name="segment_18" pos="0 0 -0.003130">
                                                            <geom type="mesh" mesh="segment_18_mesh" rgba="0.9 0.3 0.3 1"/>
                                                            <joint name="tdcr_Joint18" pos="0 0 0.00314691" axis="0 -1 0" limited="true" range="-0.523 0.523" stiffness="0.00558057" damping="0.00111613"/>
                                                            <inertial pos="0 0 0" quat="1 0 0 0" mass="0.00037143" diaginertia="4.877490e-05 4.877490e-05 6.125140e-05"/>
                                                            <site name="s18_1" pos=" 0.00240 0 0.00197" size="0.002 0.002 0.002"/>
                                                            <site name="s18_2" pos="-0.00240 0 0.00197" size="0.002 0.002 0.002"/>
                                                            <site name="s18_3" pos=" 0.00225 0 0.00020" size="0.002 0.002 0.002"/>
                                                            <site name="s18_4" pos="-0.00225 0 0.00020" size="0.002 0.002 0.002"/>
                                                            <body name="segment_19" pos="0 0 -0.003130">
                                                              <geom type="mesh" mesh="segment_19_mesh" rgba="0.9 0.3 0.3 1"/>
                                                              <joint name="tdcr_Joint19" pos="0 0 0.00314691" axis="0 -1 0" limited="true" range="-0.523 0.523" stiffness="0.00558057" damping="0.00111613"/>
                                                              <inertial pos="0 0 0" quat="1 0 0 0" mass="0.00037143" diaginertia="4.877490e-05 4.877490e-05 6.125140e-05"/>
                                                              <site name="s19_1" pos=" 0.00240 0 0.00197" size="0.002 0.002 0.002"/>
                                                              <site name="s19_2" pos="-0.00240 0 0.00197" size="0.002 0.002 0.002"/>
                                                              <site name="s19_3" pos=" 0.00225 0 0.00020" size="0.002 0.002 0.002"/>
                                                              <site name="s19_4" pos="-0.00225 0 0.00020" size="0.002 0.002 0.002"/>
                                                              <body name="segment_20" pos="0 0 -0.003130">
                                                                <geom type="mesh" mesh="segment_20_mesh" rgba="0.9 0.3 0.3 1"/>
                                                                <joint name="tdcr_Joint20" pos="0 0 0.00314691" axis="0 -1 0" limited="true" range="-0.523 0.523" stiffness="0.00558057" damping="0.00111613"/>
                                                                <inertial pos="0 0 0" quat="1 0 0 0" mass="0.00037143" diaginertia="4.877490e-05 4.877490e-05 6.125140e-05"/>
                                                                <site name="s20_1" pos=" 0.00240 0 0.00197" size="0.002 0.002 0.002"/>
                                                                <site name="s20_2" pos="-0.00240 0 0.00197" size="0.002 0.002 0.002"/>
                                                                <site name="s20_3" pos=" 0.00225 0 0.00020" size="0.002 0.002 0.002"/>
                                                                <site name="s20_4" pos="-0.00225 0 0.00020" size="0.002 0.002 0.002"/>
                                                                <body name="segment_21" pos="0 0 -0.003130">
                                                                  <geom type="mesh" mesh="segment_21_mesh" rgba="0.9 0.3 0.3 1"/>
                                                                  <joint name="tdcr_Joint21" pos="0 0 0.00314691" axis="0 -1 0" limited="true" range="-0.523 0.523" stiffness="0.00558057" damping="0.00111613"/>
                                                                  <inertial pos="0 0 0" quat="1 0 0 0" mass="0.00037143" diaginertia="4.877490e-05 4.877490e-05 6.125140e-05"/>
                                                                  <site name="s21_1" pos=" 0.00240 0 0.00197" size="0.002 0.002 0.002"/>
                                                                  <site name="s21_2" pos="-0.00240 0 0.00197" size="0.002 0.002 0.002"/>
                                                                  <site name="s21_3" pos=" 0.00225 0 0.00020" size="0.002 0.002 0.002"/>
                                                                  <site name="s21_4" pos="-0.00225 0 0.00020" size="0.002 0.002 0.002"/>
                                                                  <body name="segment_22" pos="0 0 -0.003130">
                                                                    <geom type="mesh" mesh="segment_22_mesh" rgba="0.9 0.3 0.3 1"/>
                                                                    <joint name="tdcr_Joint22" pos="0 0 0.00314691" axis="0 -1 0" limited="true" range="-0.523 0.523" stiffness="0.00558057" damping="0.00111613"/>
                                                                    <inertial pos="0 0 0" quat="1 0 0 0" mass="0.00037143" diaginertia="4.877490e-05 4.877490e-05 6.125140e-05"/>
                                                                    <site name="s22_1" pos=" 0.00240 0 0.00197" size="0.002 0.002 0.002"/>
                                                                    <site name="s22_2" pos="-0.00240 0 0.00197" size="0.002 0.002 0.002"/>
                                                                    <site name="s22_3" pos=" 0.00225 0 0.00020" size="0.002 0.002 0.002"/>
                                                                    <site name="s22_4" pos="-0.00225 0 0.00020" size="0.002 0.002 0.002"/>
                                                                    <body name="segment_23" pos="0 0 -0.003130">
                                                                      <geom type="mesh" mesh="segment_23_mesh" rgba="0.9 0.3 0.3 1"/>
                                                                      <joint name="tdcr_Joint23" pos="0 0 0.00314691" axis="0 -1 0" limited="true" range="-0.523 0.523" stiffness="0.00558057" damping="0.00111613"/>
                                                                      <inertial pos="0 0 0" quat="1 0 0 0" mass="0.00037143" diaginertia="4.877490e-05 4.877490e-05 6.125140e-05"/>
                                                                      <site name="s23_1" pos=" 0.00240 0 0.00197" size="0.002 0.002 0.002"/>
                                                                      <site name="s23_2" pos="-0.00240 0 0.00197" size="0.002 0.002 0.002"/>
                                                                      <site name="s23_3" pos=" 0.00225 0 0.00020" size="0.002 0.002 0.002"/>
                                                                      <site name="s23_4" pos="-0.00225 0 0.00020" size="0.002 0.002 0.002"/>
                                                                      <body name="segment_24" pos="0 0 -0.003130">
                                                                        <geom type="mesh" mesh="segment_24_mesh" rgba="0.9 0.3 0.3 1"/>
                                                                        <joint name="tdcr_Joint24" pos="0 0 0.00314691" axis="0 -1 0" limited="true" range="-0.523 0.523" stiffness="0.00558057" damping="0.00111613"/>
                                                                        <inertial pos="0 0 0" quat="1 0 0 0" mass="0.00037143" diaginertia="4.877490e-05 4.877490e-05 6.125140e-05"/>
                                                                        <site name="s24_1" pos=" 0.00240 0 0.00197" size="0.002 0.002 0.002"/>
                                                                        <site name="s24_2" pos="-0.00240 0 0.00197" size="0.002 0.002 0.002"/>
                                                                        <site name="s24_3" pos=" 0.00225 0 0.00020" size="0.002 0.002 0.002"/>
                                                                        <site name="s24_4" pos="-0.00225 0 0.00020" size="0.002 0.002 0.002"/>
                                                                        <body name="segment_25" pos="0 0 -0.003130">
                                                                          <geom type="mesh" mesh="segment_25_mesh" rgba="0.9 0.3 0.3 1"/>
                                                                          <joint name="tdcr_Joint25" pos="0 0 0.00314691" axis="0 -1 0" limited="true" range="-0.523 0.523" stiffness="0.00558057" damping="0.00111613"/>
                                                                          <inertial pos="0 0 0" quat="1 0 0 0" mass="0.00037143" diaginertia="4.877490e-05 4.877490e-05 6.125140e-05"/>
                                                                          <site name="s25_1" pos=" 0.00240 0 0.00197" size="0.002 0.002 0.002"/>
                                                                          <site name="s25_2" pos="-0.00240 0 0.00197" size="0.002 0.002 0.002"/>
                                                                          <site name="s25_3" pos=" 0.00225 0 0.00020" size="0.002 0.002 0.002"/>
                                                                          <site name="s25_4" pos="-0.00225 0 0.00020" size="0.002 0.002 0.002"/>
                                                                          <body name="segment_26" pos="0 0 -0.003130">
                                                                            <geom type="mesh" mesh="segment_26_mesh" rgba="0.9 0.3 0.3 1"/>
                                                                            <joint name="tdcr_Joint26" pos="0 0 0.00314691" axis="0 -1 0" limited="true" range="-0.523 0.523" stiffness="0.00558057" damping="0.00111613"/>
                                                                            <inertial pos="0 0 0" quat="1 0 0 0" mass="0.00037143" diaginertia="4.877490e-05 4.877490e-05 6.125140e-05"/>
                                                                            <site name="s26_1" pos=" 0.00240 0 0.00197" size="0.002 0.002 0.002"/>
                                                                            <site name="s26_2" pos="-0.00240 0 0.00197" size="0.002 0.002 0.002"/>
                                                                            <site name="s26_3" pos=" 0.00225 0 0.00020" size="0.002 0.002 0.002"/>
                                                                            <site name="s26_4" pos="-0.00225 0 0.00020" size="0.002 0.002 0.002"/>
                                                                            <body name="segment_27" pos="0 0 -0.003130">
                                                                              <geom type="mesh" mesh="segment_27_mesh" rgba="0.9 0.3 0.3 1"/>
                                                                              <joint name="tdcr_Joint27" pos="0 0 0.00314691" axis="0 -1 0" limited="true" range="-0.523 0.523" stiffness="0.00558057" damping="0.00111613"/>
                                                                              <inertial pos="0 0 0" quat="1 0 0 0" mass="0.00037143" diaginertia="4.877490e-05 4.877490e-05 6.125140e-05"/>
                                                                              <site name="s27_1" pos=" 0.00240 0 0.00197" size="0.002 0.002 0.002"/>
                                                                              <site name="s27_2" pos="-0.00240 0 0.00197" size="0.002 0.002 0.002"/>
                                                                              <site name="s27_3" pos=" 0.00225 0 0.00020" size="0.002 0.002 0.002"/>
                                                                              <site name="s27_4" pos="-0.00225 0 0.00020" size="0.002 0.002 0.002"/>
                                                                              <body name="segment_28" pos="0 0 -0.003130">
                                                                                <geom type="mesh" mesh="segment_28_mesh" rgba="0.9 0.3 0.3 1"/>
                                                                                <joint name="tdcr_Joint28" pos="0 0 0.00314691" axis="0 -1 0" limited="true" range="-0.523 0.523" stiffness="0.00558057" damping="0.00111613"/>
                                                                                <inertial pos="0 0 0" quat="1 0 0 0" mass="0.00037143" diaginertia="4.877490e-05 4.877490e-05 6.125140e-05"/>
                                                                                <site name="s28_1" pos=" 0.00240 0 0.00197" size="0.002 0.002 0.002"/>
                                                                                <site name="s28_2" pos="-0.00240 0 0.00197" size="0.002 0.002 0.002"/>
                                                                                <site name="s28_3" pos=" 0.00225 0 0.00020" size="0.002 0.002 0.002"/>
                                                                                <site name="s28_4" pos="-0.00225 0 0.00020" size="0.002 0.002 0.002"/>
                                                                                <body name="segment_29" pos="0 0 -0.003130">
                                                                                  <geom type="mesh" mesh="segment_29_mesh" rgba="0.9 0.3 0.3 1"/>
                                                                                  <joint name="tdcr_Joint29" pos="0 0 0.00314691" axis="0 -1 0" limited="true" range="-0.523 0.523" stiffness="0.00558057" damping="0.00111613"/>
                                                                                  <inertial pos="0 0 0" quat="1 0 0 0" mass="0.00037143" diaginertia="4.877490e-05 4.877490e-05 6.125140e-05"/>
                                                                                  <site name="s29_1" pos=" 0.00240 0 0.00197" size="0.002 0.002 0.002"/>
                                                                                  <site name="s29_2" pos="-0.00240 0 0.00197" size="0.002 0.002 0.002"/>
                                                                                  <site name="s29_3" pos=" 0.00225 0 0.00020" size="0.002 0.002 0.002"/>
                                                                                  <site name="s29_4" pos="-0.00225 0 0.00020" size="0.002 0.002 0.002"/>
                                                                                  <body name="segment_30" pos="0 0 -0.003130">
                                                                                    <geom type="mesh" mesh="segment_30_mesh" rgba="0.9 0.3 0.3 1"/>
                                                                                    <joint name="tdcr_Joint30" pos="0 0 0.00314691" axis="0 -1 0" limited="true" range="-0.523 0.523" stiffness="0.00558057" damping="0.00111613"/>
                                                                                    <inertial pos="0 0 0" quat="1 0 0 0" mass="0.00037143" diaginertia="4.877490e-05 4.877490e-05 6.125140e-05"/>
                                                                                    <site name="s30_1" pos=" 0.00240 0 0.00197" size="0.002 0.002 0.002"/>
                                                                                    <site name="s30_2" pos="-0.00240 0 0.00197" size="0.002 0.002 0.002"/>
                                                                                    <site name="s30_3" pos=" 0.00225 0 0.00020" size="0.002 0.002 0.002"/>
                                                                                    <site name="s30_4" pos="-0.00225 0 0.00020" size="0.002 0.002 0.002"/>
                                                                                    <body name="segment_31" pos="0 0 -0.003130">
                                                                                      <geom type="mesh" mesh="segment_31_mesh" rgba="0.9 0.3 0.3 1"/>
                                                                                      <joint name="tdcr_Joint31" pos="0 0 0.00314691" axis="0 -1 0" limited="true" range="-0.523 0.523" stiffness="0.00558057" damping="0.00111613"/>
                                                                                      <inertial pos="0 0 0" quat="1 0 0 0" mass="0.00037143" diaginertia="4.877490e-05 4.877490e-05 6.125140e-05"/>
                                                                                      <site name="s31_1" pos=" 0.00240 0 0.00197" size="0.002 0.002 0.002"/>
                                                                                      <site name="s31_2" pos="-0.00240 0 0.00197" size="0.002 0.002 0.002"/>
                                                                                      <site name="s31_3" pos=" 0.00225 0 0.00020" size="0.002 0.002 0.002"/>
                                                                                      <site name="s31_4" pos="-0.00225 0 0.00020" size="0.002 0.002 0.002"/>
                                                                                      <body name="segment_32" pos="0 0 -0.003130">
                                                                                        <geom type="mesh" mesh="segment_32_mesh" rgba="0.9 0.3 0.3 1"/>
                                                                                        <joint name="tdcr_Joint32" pos="0 0 0.00314691" axis="0 -1 0" limited="true" range="-0.523 0.523" stiffness="0.00558057" damping="0.00111613"/>
                                                                                        <inertial pos="0 0 0" quat="1 0 0 0" mass="0.00037143" diaginertia="4.877490e-05 4.877490e-05 6.125140e-05"/>
                                                                                        <site name="s32_1" pos=" 0.00240 0 0.00197" size="0.002 0.002 0.002"/>
                                                                                        <site name="s32_2" pos="-0.00240 0 0.00197" size="0.002 0.002 0.002"/>
                                                                                        <site name="s32_3" pos=" 0.00225 0 0.00020" size="0.002 0.002 0.002"/>
                                                                                        <site name="s32_4" pos="-0.00225 0 0.00020" size="0.002 0.002 0.002"/>
                                                                                        <body name="segment_33" pos="0 0 -0.003130">
                                                                                          <geom type="mesh" mesh="segment_33_mesh" rgba="0.9 0.3 0.3 1"/>
                                                                                          <joint name="tdcr_Joint33" pos="0 0 0.00314691" axis="0 -1 0" limited="true" range="-0.523 0.523" stiffness="0.00558057" damping="0.00111613"/>
                                                                                          <inertial pos="0 0 0" quat="1 0 0 0" mass="0.00037143" diaginertia="4.877490e-05 4.877490e-05 6.125140e-05"/>
                                                                                          <site name="s33_1" pos=" 0.00240 0 0.00197" size="0.002 0.002 0.002"/>
                                                                                          <site name="s33_2" pos="-0.00240 0 0.00197" size="0.002 0.002 0.002"/>
                                                                                          <site name="s33_3" pos=" 0.00225 0 0.00020" size="0.002 0.002 0.002"/>
                                                                                          <site name="s33_4" pos="-0.00225 0 0.00020" size="0.002 0.002 0.002"/>
                                                                                          <body name="segment_34" pos="0 0 -0.003130">
                                                                                            <geom type="mesh" mesh="segment_34_mesh" rgba="0.9 0.3 0.3 1"/>
                                                                                            <joint name="tdcr_Joint34" pos="0 0 0.00314691" axis="0 -1 0" limited="true" range="-0.523 0.523" stiffness="0.00558057" damping="0.00111613"/>
                                                                                            <inertial pos="0 0 0" quat="1 0 0 0" mass="0.00037143" diaginertia="4.877490e-05 4.877490e-05 6.125140e-05"/>
                                                                                            <site name="s34_1" pos=" 0.00240 0 0.00197" size="0.002 0.002 0.002"/>
                                                                                            <site name="s34_2" pos="-0.00240 0 0.00197" size="0.002 0.002 0.002"/>
                                                                                            <site name="s34_3" pos=" 0.00225 0 0.00020" size="0.002 0.002 0.002"/>
                                                                                            <site name="s34_4" pos="-0.00225 0 0.00020" size="0.002 0.002 0.002"/>
                                                                                            <body name="segment_35" pos="0 0 -0.003130">
                                                                                              <geom type="mesh" mesh="segment_35_mesh" rgba="0.9 0.3 0.3 1"/>
                                                                                              <joint name="tdcr_Joint35" pos="0 0 0.00314691" axis="0 -1 0" limited="true" range="-0.523 0.523" stiffness="0.00558057" damping="0.00111613"/>
                                                                                              <inertial pos="0 0 0" quat="1 0 0 0" mass="0.00037143" diaginertia="4.877490e-05 4.877490e-05 6.125140e-05"/>
                                                                                              <site name="s35_1" pos=" 0.00240 0 0.00197" size="0.002 0.002 0.002"/>
                                                                                              <site name="s35_2" pos="-0.00240 0 0.00197" size="0.002 0.002 0.002"/>
                                                                                              <site name="s35_3" pos=" 0.00225 0 0.00020" size="0.002 0.002 0.002"/>
                                                                                              <site name="s35_4" pos="-0.00225 0 0.00020" size="0.002 0.002 0.002"/>
                                                                                              <body name="segment_36" pos="0 0 -0.003130">
                                                                                                <geom type="mesh" mesh="segment_36_mesh" rgba="0.9 0.3 0.3 1"/>
                                                                                                <joint name="tdcr_Joint36" pos="0 0 0.00314691" axis="0 -1 0" limited="true" range="-0.523 0.523" stiffness="0.00558057" damping="0.00111613"/>
                                                                                                <inertial pos="0 0 0" quat="1 0 0 0" mass="0.00037143" diaginertia="4.877490e-05 4.877490e-05 6.125140e-05"/>
                                                                                                <site name="s36_1" pos=" 0.00240 0 0.00197" size="0.002 0.002 0.002"/>
                                                                                                <site name="s36_2" pos="-0.00240 0 0.00197" size="0.002 0.002 0.002"/>
                                                                                                <site name="s36_3" pos=" 0.00225 0 0.00020" size="0.002 0.002 0.002"/>
                                                                                                <site name="s36_4" pos="-0.00225 0 0.00020" size="0.002 0.002 0.002"/>
                                                                                                <body name="segment_37" pos="0 0 -0.003130">
                                                                                                  <geom type="mesh" mesh="segment_37_mesh" rgba="0.9 0.3 0.3 1"/>
                                                                                                  <joint name="tdcr_Joint37" pos="0 0 0.00314691" axis="0 -1 0" limited="true" range="-0.523 0.523" stiffness="0.00558057" damping="0.00111613"/>
                                                                                                  <inertial pos="0 0 0" quat="1 0 0 0" mass="0.00037143" diaginertia="4.877490e-05 4.877490e-05 6.125140e-05"/>
                                                                                                  <site name="s37_1" pos=" 0.00240 0 0.00197" size="0.002 0.002 0.002"/>
                                                                                                  <site name="s37_2" pos="-0.00240 0 0.00197" size="0.002 0.002 0.002"/>
                                                                                                  <site name="s37_3" pos=" 0.00225 0 0.00020" size="0.002 0.002 0.002"/>
                                                                                                  <site name="s37_4" pos="-0.00225 0 0.00020" size="0.002 0.002 0.002"/>
                                                                                                  <body name="segment_38" pos="0 0 -0.003130">
                                                                                                    <geom type="mesh" mesh="segment_38_mesh" rgba="0.9 0.3 0.3 1"/>
                                                                                                    <joint name="tdcr_Joint38" pos="0 0 0.00314691" axis="0 -1 0" limited="true" range="-0.523 0.523" stiffness="0.00558057" damping="0.00111613"/>
                                                                                                    <inertial pos="0 0 0" quat="1 0 0 0" mass="0.00037143" diaginertia="4.877490e-05 4.877490e-05 6.125140e-05"/>
                                                                                                    <site name="s38_1" pos=" 0.00240 0 0.00197" size="0.002 0.002 0.002"/>
                                                                                                    <site name="s38_2" pos="-0.00240 0 0.00197" size="0.002 0.002 0.002"/>
                                                                                                    <site name="s38_3" pos=" 0.00225 0 0.00020" size="0.002 0.002 0.002"/>
                                                                                                    <site name="s38_4" pos="-0.00225 0 0.00020" size="0.002 0.002 0.002"/>
                                                                                                    <body name="segment_39" pos="0 0 -0.003130">
                                                                                                      <geom type="mesh" mesh="segment_39_mesh" rgba="0.9 0.3 0.3 1"/>
                                                                                                      <joint name="tdcr_Joint39" pos="0 0 0.00314691" axis="0 -1 0" limited="true" range="-0.523 0.523" stiffness="0.00558057" damping="0.00111613"/>
                                                                                                      <inertial pos="0 0 0" quat="1 0 0 0" mass="0.00037143" diaginertia="4.877490e-05 4.877490e-05 6.125140e-05"/>
                                                                                                      <site name="s39_1" pos=" 0.00240 0 0.00197" size="0.002 0.002 0.002"/>
                                                                                                      <site name="s39_2" pos="-0.00240 0 0.00197" size="0.002 0.002 0.002"/>
                                                                                                      <site name="s39_3" pos=" 0.00225 0 0.00020" size="0.002 0.002 0.002"/>
                                                                                                      <site name="s39_4" pos="-0.00225 0 0.00020" size="0.002 0.002 0.002"/>
                                                                                                      <body name="segment_40" pos="0 0 -0.003130">
                                                                                                        <geom type="mesh" mesh="segment_40_mesh" rgba="0.9 0.3 0.3 1"/>
                                                                                                        <joint name="tdcr_Joint40" pos="0 0 0.00314691" axis="0 -1 0" limited="true" range="-0.523 0.523" stiffness="0.00558057" damping="0.00111613"/>
                                                                                                        <inertial pos="0 0 0" quat="1 0 0 0" mass="0.00037143" diaginertia="4.877490e-05 4.877490e-05 6.125140e-05"/>
                                                                                                        <site name="s40_1" pos=" 0.00240 0 0.00197" size="0.002 0.002 0.002"/>
                                                                                                        <site name="s40_2" pos="-0.00240 0 0.00197" size="0.002 0.002 0.002"/>
                                                                                                        <site name="s40_3" pos=" 0.00225 0 0.00020" size="0.002 0.002 0.002"/>
                                                                                                        <site name="s40_4" pos="-0.00225 0 0.00020" size="0.002 0.002 0.002"/>
                                                                                                        <body name="segment_41" pos="0 0 -0.003130">
                                                                                                          <geom type="mesh" mesh="segment_41_mesh" rgba="0.9 0.3 0.3 1"/>
                                                                                                          <joint name="tdcr_Joint41" pos="0 0 0.00314691" axis="0 -1 0" limited="true" range="-0.523 0.523" stiffness="0.00558057" damping="0.00111613"/>
                                                                                                          <inertial pos="0 0 0" quat="1 0 0 0" mass="0.00037143" diaginertia="4.877490e-05 4.877490e-05 6.125140e-05"/>
                                                                                                          <site name="s41_1" pos=" 0.00240 0 0.00197" size="0.002 0.002 0.002"/>
                                                                                                          <site name="s41_2" pos="-0.00240 0 0.00197" size="0.002 0.002 0.002"/>
                                                                                                          <site name="s41_3" pos=" 0.00225 0 0.00020" size="0.002 0.002 0.002"/>
                                                                                                          <site name="s41_4" pos="-0.00225 0 0.00020" size="0.002 0.002 0.002"/>
                                                                                                          <body name="segment_42" pos="0 0 -0.003130">
                                                                                                            <geom type="mesh" mesh="segment_42_mesh" rgba="0.9 0.3 0.3 1"/>
                                                                                                            <joint name="tdcr_Joint42" pos="0 0 0.00314691" axis="0 -1 0" limited="true" range="-0.523 0.523" stiffness="0.00558057" damping="0.00111613"/>
                                                                                                            <inertial pos="0 0 0" quat="1 0 0 0" mass="0.00037143" diaginertia="4.877490e-05 4.877490e-05 6.125140e-05"/>
                                                                                                            <site name="s42_1" pos=" 0.00240 0 0.00197" size="0.002 0.002 0.002"/>
                                                                                                            <site name="s42_2" pos="-0.00240 0 0.00197" size="0.002 0.002 0.002"/>
                                                                                                            <site name="s42_3" pos=" 0.00225 0 0.00020" size="0.002 0.002 0.002"/>
                                                                                                            <site name="s42_4" pos="-0.00225 0 0.00020" size="0.002 0.002 0.002"/>
                                                                                                            <body name="segment_43" pos="0 0 -0.003130">
                                                                                                              <geom type="mesh" mesh="segment_43_mesh" rgba="0.9 0.3 0.3 1"/>
                                                                                                              <joint name="tdcr_Joint43" pos="0 0 0.00314691" axis="0 -1 0" limited="true" range="-0.523 0.523" stiffness="0.00558057" damping="0.00111613"/>
                                                                                                              <inertial pos="0 0 0" quat="1 0 0 0" mass="0.00037143" diaginertia="4.877490e-05 4.877490e-05 6.125140e-05"/>
                                                                                                              <site name="s43_1" pos=" 0.00240 0 0.00197" size="0.002 0.002 0.002"/>
                                                                                                              <site name="s43_2" pos="-0.00240 0 0.00197" size="0.002 0.002 0.002"/>
                                                                                                              <site name="s43_3" pos=" 0.00225 0 0.00020" size="0.002 0.002 0.002"/>
                                                                                                              <site name="s43_4" pos="-0.00225 0 0.00020" size="0.002 0.002 0.002"/>
                                                                                                              <body name="segment_44" pos="0 0 -0.003130">
                                                                                                                <geom type="mesh" mesh="segment_44_mesh" rgba="0.9 0.3 0.3 1"/>
                                                                                                                <joint name="tdcr_Joint44" pos="0 0 0.00314691" axis="0 -1 0" limited="true" range="-0.523 0.523" stiffness="0.00558057" damping="0.00111613"/>
                                                                                                                <inertial pos="0 0 0" quat="1 0 0 0" mass="0.00037143" diaginertia="4.877490e-05 4.877490e-05 6.125140e-05"/>
                                                                                                                <site name="s44_1" pos=" 0.00240 0 0.00197" size="0.002 0.002 0.002"/>
                                                                                                                <site name="s44_2" pos="-0.00240 0 0.00197" size="0.002 0.002 0.002"/>
                                                                                                                <site name="s44_3" pos=" 0.00225 0 0.00020" size="0.002 0.002 0.002"/>
                                                                                                                <site name="s44_4" pos="-0.00225 0 0.00020" size="0.002 0.002 0.002"/>
                                                                                                                <body name="segment_45" pos="0 0 -0.003130">
                                                                                                                  <geom type="mesh" mesh="segment_45_mesh" rgba="0.9 0.3 0.3 1"/>
                                                                                                                  <joint name="tdcr_Joint45" pos="0 0 0.00314691" axis="0 -1 0" limited="true" range="-0.523 0.523" stiffness="0.00558057" damping="0.00111613"/>
                                                                                                                  <inertial pos="0 0 0" quat="1 0 0 0" mass="0.00037143" diaginertia="4.877490e-05 4.877490e-05 6.125140e-05"/>
                                                                                                                  <site name="s45_1" pos=" 0.00240 0 0.00197" size="0.002 0.002 0.002"/>
                                                                                                                  <site name="s45_2" pos="-0.00240 0 0.00197" size="0.002 0.002 0.002"/>
                                                                                                                  <site name="s45_3" pos=" 0.00225 0 0.00020" size="0.002 0.002 0.002"/>
                                                                                                                  <site name="s45_4" pos="-0.00225 0 0.00020" size="0.002 0.002 0.002"/>
                                                                                                                  <body name="segment_46" pos="0 0 -0.003130">
                                                                                                                    <geom type="mesh" mesh="segment_46_mesh" rgba="0.9 0.3 0.3 1"/>
                                                                                                                    <joint name="tdcr_Joint46" pos="0 0 0.00314691" axis="0 -1 0" limited="true" range="-0.523 0.523" stiffness="0.00558057" damping="0.00111613"/>
                                                                                                                    <inertial pos="0 0 0" quat="1 0 0 0" mass="0.00037143" diaginertia="4.877490e-05 4.877490e-05 6.125140e-05"/>
                                                                                                                    <site name="s46_1" pos=" 0.00240 0 0.00197" size="0.002 0.002 0.002"/>
                                                                                                                    <site name="s46_2" pos="-0.00240 0 0.00197" size="0.002 0.002 0.002"/>
                                                                                                                    <site name="s46_3" pos=" 0.00225 0 0.00020" size="0.002 0.002 0.002"/>
                                                                                                                    <site name="s46_4" pos="-0.00225 0 0.00020" size="0.002 0.002 0.002"/>
                                                                                                                    <body name="segment_47" pos="0 0 -0.003130">
                                                                                                                      <geom type="mesh" mesh="segment_47_mesh" rgba="0.9 0.3 0.3 1"/>
                                                                                                                      <joint name="tdcr_Joint47" pos="0 0 0.00314691" axis="0 -1 0" limited="true" range="-0.523 0.523" stiffness="0.00558057" damping="0.00111613"/>
                                                                                                                      <inertial pos="0 0 0" quat="1 0 0 0" mass="0.00037143" diaginertia="4.877490e-05 4.877490e-05 6.125140e-05"/>
                                                                                                                      <site name="s47_1" pos=" 0.00240 0 0.00197" size="0.002 0.002 0.002"/>
                                                                                                                      <site name="s47_2" pos="-0.00240 0 0.00197" size="0.002 0.002 0.002"/>
                                                                                                                      <site name="s47_3" pos=" 0.00225 0 0.00020" size="0.002 0.002 0.002"/>
                                                                                                                      <site name="s47_4" pos="-0.00225 0 0.00020" size="0.002 0.002 0.002"/>
                                                                                                                      <body name="segment_48" pos="0 0 -0.003130">
                                                                                                                        <geom type="mesh" mesh="segment_48_mesh" rgba="0.9 0.3 0.3 1"/>
                                                                                                                        <joint name="tdcr_Joint48" pos="0 0 0.00314691" axis="0 -1 0" limited="true" range="-0.523 0.523" stiffness="0.00558057" damping="0.00111613"/>
                                                                                                                        <inertial pos="0 0 0" quat="1 0 0 0" mass="0.00037143" diaginertia="4.877490e-05 4.877490e-05 6.125140e-05"/>
                                                                                                                        <site name="s48_1" pos=" 0.00240 0 0.00197" size="0.002 0.002 0.002"/>
                                                                                                                        <site name="s48_2" pos="-0.00240 0 0.00197" size="0.002 0.002 0.002"/>
                                                                                                                        <site name="s48_3" pos=" 0.00225 0 0.00020" size="0.002 0.002 0.002"/>
                                                                                                                        <site name="s48_4" pos="-0.00225 0 0.00020" size="0.002 0.002 0.002"/>
                                                                                                                        <body name="segment_49" pos="0 0 -0.003130">
                                                                                                                          <geom type="mesh" mesh="segment_49_mesh" rgba="0.9 0.3 0.3 1"/>
                                                                                                                          <joint name="tdcr_Joint49" pos="0 0 0.00314691" axis="0 -1 0" limited="true" range="-0.523 0.523" stiffness="0.00558057" damping="0.00111613"/>
                                                                                                                          <inertial pos="0 0 0" quat="1 0 0 0" mass="0.00037143" diaginertia="4.877490e-05 4.877490e-05 6.125140e-05"/>
                                                                                                                          <site name="s49_1" pos=" 0.00240 0 0.00197" size="0.002 0.002 0.002"/>
                                                                                                                          <site name="s49_2" pos="-0.00240 0 0.00197" size="0.002 0.002 0.002"/>
                                                                                                                          <site name="s49_3" pos=" 0.00225 0 0.00020" size="0.002 0.002 0.002"/>
                                                                                                                          <site name="s49_4" pos="-0.00225 0 0.00020" size="0.002 0.002 0.002"/>
                                                                                                                          <body name="segment_50" pos="0 0 -0.003130">
                                                                                                                            <geom type="mesh" mesh="segment_50_mesh" rgba="0.9 0.3 0.3 1"/>
                                                                                                                            <joint name="tdcr_Joint50" pos="0 0 0.00314691" axis="0 -1 0" limited="true" range="-0.523 0.523" stiffness="0.00558057" damping="0.00111613"/>
                                                                                                                            <inertial pos="0 0 0" quat="1 0 0 0" mass="0.00037143" diaginertia="4.877490e-05 4.877490e-05 6.125140e-05"/>
                                                                                                                            <site name="s50_1" pos=" 0.00240 0 0.00197" size="0.002 0.002 0.002"/>
                                                                                                                            <site name="s50_2" pos="-0.00240 0 0.00197" size="0.002 0.002 0.002"/>
                                                                                                                            <site name="s50_3" pos=" 0.00225 0 0.00020" size="0.002 0.002 0.002"/>
                                                                                                                            <site name="s50_4" pos="-0.00225 0 0.00020" size="0.002 0.002 0.002"/>
                                                                                                                            <body name="tdcr_gripper_base" pos="0 0 0" euler="0 3.14159 0">
                                                                                                                              <geom type="mesh" mesh="gripper_base" rgba="0.6 0.6 0.6 1"/>
                                                                                                                              <site name="base_1" pos="0 0 0.002" size="0.002 0.002 0.002"/>
                                                                                                                              <site name="tdcr_tip" pos="0 0 0.005" size="0.003 0.003 0.003" rgba="1 1 0 1"/>
                                                                                                                              <body name="gripper_1" pos="0.00231 0 0.00355">
                                                                                                                                <geom type="mesh" mesh="gripper" rgba="0.9 0.9 0.9 1" friction="2 0.01 0.001"/>
                                                                                                                                <joint name="gripper_1_joint" type="hinge" pos="0 0 0" axis="0 1 0" range="-45 0" limited="true" stiffness="5" damping="0.5"/>
                                                                                                                                <site name="grip_1" pos="-0.00185 0 0" size="0.002 0.002 0.002"/>
                                                                                                                              </body>
                                                                                                                              <body name="gripper_2" pos="-0.00231 0 0.00355" euler="0 0 3.14159">
                                                                                                                                <geom type="mesh" mesh="gripper" rgba="1 1 1 1" friction="2 0.01 0.001"/>
                                                                                                                                <joint name="gripper_2_joint" type="hinge" pos="0 0 0" axis="0 -1 0" range="0 45" limited="true" stiffness="5" damping="0.5"/>
                                                                                                                                <site name="grip_2" pos="-0.00185 0 0" size="0.002 0.002 0.002"/>
                                                                                                                              </body>
                                                                                                                            </body>
                                                                                                                          </body><!-- segment_50 -->
                                                                                                                        </body><!-- segment_49 -->
                                                                                                                      </body><!-- segment_48 -->
                                                                                                                    </body><!-- segment_47 -->
                                                                                                                  </body><!-- segment_46 -->
                                                                                                                </body><!-- segment_45 -->
                                                                                                              </body><!-- segment_44 -->
                                                                                                            </body><!-- segment_43 -->
                                                                                                          </body><!-- segment_42 -->
                                                                                                        </body><!-- segment_41 -->
                                                                                                      </body><!-- segment_40 -->
                                                                                                    </body><!-- segment_39 -->
                                                                                                  </body><!-- segment_38 -->
                                                                                                </body><!-- segment_37 -->
                                                                                              </body><!-- segment_36 -->
                                                                                            </body><!-- segment_35 -->
                                                                                          </body><!-- segment_34 -->
                                                                                        </body><!-- segment_33 -->
                                                                                      </body><!-- segment_32 -->
                                                                                    </body><!-- segment_31 -->
                                                                                  </body><!-- segment_30 -->
                                                                                </body><!-- segment_29 -->
                                                                              </body><!-- segment_28 -->
                                                                            </body><!-- segment_27 -->
                                                                          </body><!-- segment_26 -->
                                                                        </body><!-- segment_25 -->
                                                                      </body><!-- segment_24 -->
                                                                    </body><!-- segment_23 -->
                                                                  </body><!-- segment_22 -->
                                                                </body><!-- segment_21 -->
                                                              </body><!-- segment_20 -->
                                                            </body><!-- segment_19 -->
                                                          </body><!-- segment_18 -->
                                                        </body><!-- segment_17 -->
                                                      </body><!-- segment_16 -->
                                                    </body><!-- segment_15 -->
                                                  </body><!-- segment_14 -->
                                                </body><!-- segment_13 -->
                                              </body><!-- segment_12 -->
                                            </body><!-- segment_11 -->
                                          </body><!-- segment_10 -->
                                        </body><!-- segment_9 -->
                                      </body><!-- segment_8 -->
                                    </body><!-- segment_7 -->
                                  </body><!-- segment_6 -->
                                </body><!-- segment_5 -->
                              </body><!-- segment_4 -->
                            </body><!-- segment_3 -->
                          </body><!-- segment_2 -->
                        </body><!-- segment_1 -->
                      </body><!-- tdcr_platform -->
                    </body><!-- attachment -->

                  </body><!-- link7 -->
                </body><!-- link6 -->
              </body><!-- link5 -->
            </body><!-- link4 -->
          </body><!-- link3 -->
        </body><!-- link2 -->
      </body><!-- link1 -->
    </body><!-- link0 -->

  </worldbody>

  <!-- ═══ TENDONS ═══ -->
  <tendon>
    <spatial name="t1" width="0.0004" frictionloss="0.1" rgba=".95 .3 .3 1" limited="true" range="0.05 0.2">
      <site site="b_2"/>
      <site site="s1_1"/>  <site site="s1_3"/>
      <site site="s2_1"/>  <site site="s2_3"/>
      <site site="s3_1"/>  <site site="s3_3"/>
      <site site="s4_1"/>  <site site="s4_3"/>
      <site site="s5_1"/>  <site site="s5_3"/>
      <site site="s6_1"/>  <site site="s6_3"/>
      <site site="s7_1"/>  <site site="s7_3"/>
      <site site="s8_1"/>  <site site="s8_3"/>
      <site site="s9_1"/>  <site site="s9_3"/>
      <site site="s10_1"/>  <site site="s10_3"/>
      <site site="s11_1"/>  <site site="s11_3"/>
      <site site="s12_1"/>  <site site="s12_3"/>
      <site site="s13_1"/>  <site site="s13_3"/>
      <site site="s14_1"/>  <site site="s14_3"/>
      <site site="s15_1"/>  <site site="s15_3"/>
      <site site="s16_1"/>  <site site="s16_3"/>
      <site site="s17_1"/>  <site site="s17_3"/>
      <site site="s18_1"/>  <site site="s18_3"/>
      <site site="s19_1"/>  <site site="s19_3"/>
      <site site="s20_1"/>  <site site="s20_3"/>
      <site site="s21_1"/>  <site site="s21_3"/>
      <site site="s22_1"/>  <site site="s22_3"/>
      <site site="s23_1"/>  <site site="s23_3"/>
      <site site="s24_1"/>  <site site="s24_3"/>
      <site site="s25_1"/>  <site site="s25_3"/>
      <site site="s26_1"/>  <site site="s26_3"/>
      <site site="s27_1"/>  <site site="s27_3"/>
      <site site="s28_1"/>  <site site="s28_3"/>
      <site site="s29_1"/>  <site site="s29_3"/>
      <site site="s30_1"/>  <site site="s30_3"/>
      <site site="s31_1"/>  <site site="s31_3"/>
      <site site="s32_1"/>  <site site="s32_3"/>
      <site site="s33_1"/>  <site site="s33_3"/>
      <site site="s34_1"/>  <site site="s34_3"/>
      <site site="s35_1"/>  <site site="s35_3"/>
      <site site="s36_1"/>  <site site="s36_3"/>
      <site site="s37_1"/>  <site site="s37_3"/>
      <site site="s38_1"/>  <site site="s38_3"/>
      <site site="s39_1"/>  <site site="s39_3"/>
      <site site="s40_1"/>  <site site="s40_3"/>
      <site site="s41_1"/>  <site site="s41_3"/>
      <site site="s42_1"/>  <site site="s42_3"/>
      <site site="s43_1"/>  <site site="s43_3"/>
      <site site="s44_1"/>  <site site="s44_3"/>
      <site site="s45_1"/>  <site site="s45_3"/>
      <site site="s46_1"/>  <site site="s46_3"/>
      <site site="s47_1"/>  <site site="s47_3"/>
      <site site="s48_1"/>  <site site="s48_3"/>
      <site site="s49_1"/>  <site site="s49_3"/>
      <site site="s50_1"/>  <site site="s50_3"/>
    </spatial>
    <spatial name="t2" width="0.0004" frictionloss="0.1" rgba=".95 .3 .3 1" limited="true" range="0.05 0.2">
      <site site="b_1"/>
      <site site="s1_2"/>  <site site="s1_4"/>
      <site site="s2_2"/>  <site site="s2_4"/>
      <site site="s3_2"/>  <site site="s3_4"/>
      <site site="s4_2"/>  <site site="s4_4"/>
      <site site="s5_2"/>  <site site="s5_4"/>
      <site site="s6_2"/>  <site site="s6_4"/>
      <site site="s7_2"/>  <site site="s7_4"/>
      <site site="s8_2"/>  <site site="s8_4"/>
      <site site="s9_2"/>  <site site="s9_4"/>
      <site site="s10_2"/>  <site site="s10_4"/>
      <site site="s11_2"/>  <site site="s11_4"/>
      <site site="s12_2"/>  <site site="s12_4"/>
      <site site="s13_2"/>  <site site="s13_4"/>
      <site site="s14_2"/>  <site site="s14_4"/>
      <site site="s15_2"/>  <site site="s15_4"/>
      <site site="s16_2"/>  <site site="s16_4"/>
      <site site="s17_2"/>  <site site="s17_4"/>
      <site site="s18_2"/>  <site site="s18_4"/>
      <site site="s19_2"/>  <site site="s19_4"/>
      <site site="s20_2"/>  <site site="s20_4"/>
      <site site="s21_2"/>  <site site="s21_4"/>
      <site site="s22_2"/>  <site site="s22_4"/>
      <site site="s23_2"/>  <site site="s23_4"/>
      <site site="s24_2"/>  <site site="s24_4"/>
      <site site="s25_2"/>  <site site="s25_4"/>
      <site site="s26_2"/>  <site site="s26_4"/>
      <site site="s27_2"/>  <site site="s27_4"/>
      <site site="s28_2"/>  <site site="s28_4"/>
      <site site="s29_2"/>  <site site="s29_4"/>
      <site site="s30_2"/>  <site site="s30_4"/>
      <site site="s31_2"/>  <site site="s31_4"/>
      <site site="s32_2"/>  <site site="s32_4"/>
      <site site="s33_2"/>  <site site="s33_4"/>
      <site site="s34_2"/>  <site site="s34_4"/>
      <site site="s35_2"/>  <site site="s35_4"/>
      <site site="s36_2"/>  <site site="s36_4"/>
      <site site="s37_2"/>  <site site="s37_4"/>
      <site site="s38_2"/>  <site site="s38_4"/>
      <site site="s39_2"/>  <site site="s39_4"/>
      <site site="s40_2"/>  <site site="s40_4"/>
      <site site="s41_2"/>  <site site="s41_4"/>
      <site site="s42_2"/>  <site site="s42_4"/>
      <site site="s43_2"/>  <site site="s43_4"/>
      <site site="s44_2"/>  <site site="s44_4"/>
      <site site="s45_2"/>  <site site="s45_4"/>
      <site site="s46_2"/>  <site site="s46_4"/>
      <site site="s47_2"/>  <site site="s47_4"/>
      <site site="s48_2"/>  <site site="s48_4"/>
      <site site="s49_2"/>  <site site="s49_4"/>
      <site site="s50_2"/>  <site site="s50_4"/>
    </spatial>
    <spatial name="g1" width="0.0004" frictionloss="0.1" rgba=".95 .3 .3 1" limited="true" range="0.0009 0.00166">
      <site site="base_1"/><site site="grip_1"/>
    </spatial>
    <spatial name="g2" width="0.0004" frictionloss="0.1" rgba=".95 .3 .3 1" limited="true" range="0.0009 0.00166">
      <site site="base_1"/><site site="grip_2"/>
    </spatial>
  </tendon>

  <!-- ═══ ACTUATORS ═══
       Indices 0-6  : Panda arm joints (position servos)
       Index   7    : A_1 — TDCR bend tendon 1
       Index   8    : A_2 — TDCR bend tendon 2
       Index   9    : A_3 — TDCR gripper 1
       Index   10   : A_4 — TDCR gripper 2
  -->
  <actuator>
    <!-- Panda arm (position servos, indices 0-6) -->
    <general class="panda" name="actuator1" joint="joint1" gainprm="4500" biasprm="0 -4500 -450"/>
    <general class="panda" name="actuator2" joint="joint2" gainprm="4500" biasprm="0 -4500 -450" ctrlrange="-1.7628 1.7628"/>
    <general class="panda" name="actuator3" joint="joint3" gainprm="3500" biasprm="0 -3500 -350"/>
    <general class="panda" name="actuator4" joint="joint4" gainprm="3500" biasprm="0 -3500 -350" ctrlrange="-3.0718 -0.0698"/>
    <general class="panda" name="actuator5" joint="joint5" gainprm="2000" biasprm="0 -2000 -200" forcerange="-12 12"/>
    <general class="panda" name="actuator6" joint="joint6" gainprm="2000" biasprm="0 -2000 -200" forcerange="-12 12" ctrlrange="-0.0175 3.7525"/>
    <general class="panda" name="actuator7" joint="joint7" gainprm="2000" biasprm="0 -2000 -200" forcerange="-12 12"/>
    <!-- TDCR muscle actuators (indices 7-10) -->
    <muscle name="A_1" ctrllimited="true" lengthrange="0.05 0.2"       ctrlrange="0 1" force="2"     tendon="t1"/>
    <muscle name="A_2" ctrllimited="true" lengthrange="0.05 0.2"       ctrlrange="0 1" force="2"     tendon="t2"/>
    <muscle name="A_3" ctrllimited="true" lengthrange="0.0009 0.00166" ctrlrange="0 1" force="300.5" tendon="g1"/>
    <muscle name="A_4" ctrllimited="true" lengthrange="0.0009 0.00166" ctrlrange="0 1" force="300.5" tendon="g2"/>
  </actuator>

  <contact>
    <exclude body1="link0" body2="link1"/>
  </contact>

  <!-- ═══ KEYFRAME ═══
       qpos: 7 (arm) + 50 (tdcr) + 2 (gripper) = 59 values
       ctrl: 7 (arm) + 4 (tdcr) = 11 values  -->
  <keyframe>
    <key name="home"
      qpos="0 0 0 -1.57079 0 1.57079 -0.7853
            0 0 0 0 0 0 0 0 0 0 0 0 0 0 0 0 0 0 0 0 0 0 0 0 0 0 0 0 0 0 0 0 0 0 0 0 0 0 0 0 0 0 0 0 0 0 0 0 0 0 0 0"
      ctrl="0 0 0 -1.57079 0 1.57079 -0.7853
            0 0 0 0"/>
  </keyframe>

</mujoco>